Workbook

Sheet 1_INPUT_DATA
A1: COSTBREAKDOWN — MASTER OPERATIONAL INPUT DATA (BLANK TEMPLATE)
A2: Fill operational parameters in yellow cells. All calculations run automatically in Sheet 2-4.
A4: PRODUCT INFO
A5: Product Code | B5: Product Name / Description | C5: Base Qty | D5: UOM | E5: Customer / Application | F5: Source Reference
A8: WORK CENTER RATES (THB / MHr)
A9: Work Center (WC) | B9: Department Description | C9: Labor Rate (THB/MHr) | D9: Burden Rate (THB/MHr) | E9: Effective Date | F9: Source Reference
A15: BOM (MATERIAL INPUT) — 10 ITEMS
A16: Item No | B16: Material Code | C16: Material Description | D16: Consumption (Q) | E16: UOM | F16: Base Price (P0) | G16: Active Price (P1) | H16: Base Loss % | I16: Active Loss % | J16: Source Reference
A28: ROUTING (PROCESS INPUT) — 12 OPERATIONS
A29: Seq | B29: Process Name | C29: Work Center | D29: Man (M) | E29: Base Capacity (pc/hr) | F29: Active Capacity (pc/hr) | G29: Base Cycle Time (s) | H29: Active Cycle Time (s) | I29: Base Yield (%) | J29: Active Yield (%) | K29: Source Reference

Sheet 2_COST_BREAKDOWN
A1: PRODUCT COST BREAKDOWN & LEVEL 1-3 VARIANCE ANALYSIS
A2: Dynamic calculation engine referencing Sheet 1 inputs. 100% automated formulas.
A4: PART 1: DIRECT MATERIAL COST & VARIANCE (BOM)
A5: Item No | B5: Material Code | C5: Material Description | D5: Base Cost (฿) | E5: Active Cost (฿) | F5: Price Var (MPV) (฿) | G5: Loss Var (MLV) (฿) | H5: Total Mat Var (Δ ฿)
A6: =IFERROR(IF('1_INPUT_DATA'!A17="","",'1_INPUT_DATA'!A17),"") | B6: =IFERROR(IF('1_INPUT_DATA'!B17="","",'1_INPUT_DATA'!B17),"") | C6: =IFERROR(IF('1_INPUT_DATA'!C17="","",'1_INPUT_DATA'!C17),"") | D6: =IFERROR(IF('1_INPUT_DATA'!B17="","", '1_INPUT_DATA'!D17*'1_INPUT_DATA'!F17*(1+'1_INPUT_DATA'!H17)),"") | E6: =IFERROR(IF('1_INPUT_DATA'!B17="","", '1_INPUT_DATA'!D17*'1_INPUT_DATA'!G17*(1+'1_INPUT_DATA'!I17)),"") | F6: =IFERROR(IF('1_INPUT_DATA'!B17="","", ('1_INPUT_DATA'!G17-'1_INPUT_DATA'!F17)*'1_INPUT_DATA'!D17*(1+'1_INPUT_DATA'!I17)),"") | G6: =IFERROR(IF('1_INPUT_DATA'!B17="","", ('1_INPUT_DATA'!I17-'1_INPUT_DATA'!H17)*'1_INPUT_DATA'!D17*'1_INPUT_DATA'!F17),"") | H6: =IFERROR(IF('1_INPUT_DATA'!B17="","", E6-D6),"")
A7: =IFERROR(IF('1_INPUT_DATA'!A18="","",'1_INPUT_DATA'!A18),"") | B7: =IFERROR(IF('1_INPUT_DATA'!B18="","",'1_INPUT_DATA'!B18),"") | C7: =IFERROR(IF('1_INPUT_DATA'!C18="","",'1_INPUT_DATA'!C18),"") | D7: =IFERROR(IF('1_INPUT_DATA'!B18="","", '1_INPUT_DATA'!D18*'1_INPUT_DATA'!F18*(1+'1_INPUT_DATA'!H18)),"") | E7: =IFERROR(IF('1_INPUT_DATA'!B18="","", '1_INPUT_DATA'!D18*'1_INPUT_DATA'!G18*(1+'1_INPUT_DATA'!I18)),"") | F7: =IFERROR(IF('1_INPUT_DATA'!B18="","", ('1_INPUT_DATA'!G18-'1_INPUT_DATA'!F18)*'1_INPUT_DATA'!D18*(1+'1_INPUT_DATA'!I18)),"") | G7: =IFERROR(IF('1_INPUT_DATA'!B18="","", ('1_INPUT_DATA'!I18-'1_INPUT_DATA'!H18)*'1_INPUT_DATA'!D18*'1_INPUT_DATA'!F18),"") | H7: =IFERROR(IF('1_INPUT_DATA'!B18="","", E7-D7),"")
A8: =IFERROR(IF('1_INPUT_DATA'!A19="","",'1_INPUT_DATA'!A19),"") | B8: =IFERROR(IF('1_INPUT_DATA'!B19="","",'1_INPUT_DATA'!B19),"") | C8: =IFERROR(IF('1_INPUT_DATA'!C19="","",'1_INPUT_DATA'!C19),"") | D8: =IFERROR(IF('1_INPUT_DATA'!B19="","", '1_INPUT_DATA'!D19*'1_INPUT_DATA'!F19*(1+'1_INPUT_DATA'!H19)),"") | E8: =IFERROR(IF('1_INPUT_DATA'!B19="","", '1_INPUT_DATA'!D19*'1_INPUT_DATA'!G19*(1+'1_INPUT_DATA'!I19)),"") | F8: =IFERROR(IF('1_INPUT_DATA'!B19="","", ('1_INPUT_DATA'!G19-'1_INPUT_DATA'!F19)*'1_INPUT_DATA'!D19*(1+'1_INPUT_DATA'!I19)),"") | G8: =IFERROR(IF('1_INPUT_DATA'!B19="","", ('1_INPUT_DATA'!I19-'1_INPUT_DATA'!H19)*'1_INPUT_DATA'!D19*'1_INPUT_DATA'!F19),"") | H8: =IFERROR(IF('1_INPUT_DATA'!B19="","", E8-D8),"")
A9: =IFERROR(IF('1_INPUT_DATA'!A20="","",'1_INPUT_DATA'!A20),"") | B9: =IFERROR(IF('1_INPUT_DATA'!B20="","",'1_INPUT_DATA'!B20),"") | C9: =IFERROR(IF('1_INPUT_DATA'!C20="","",'1_INPUT_DATA'!C20),"") | D9: =IFERROR(IF('1_INPUT_DATA'!B20="","", '1_INPUT_DATA'!D20*'1_INPUT_DATA'!F20*(1+'1_INPUT_DATA'!H20)),"") | E9: =IFERROR(IF('1_INPUT_DATA'!B20="","", '1_INPUT_DATA'!D20*'1_INPUT_DATA'!G20*(1+'1_INPUT_DATA'!I20)),"") | F9: =IFERROR(IF('1_INPUT_DATA'!B20="","", ('1_INPUT_DATA'!G20-'1_INPUT_DATA'!F20)*'1_INPUT_DATA'!D20*(1+'1_INPUT_DATA'!I20)),"") | G9: =IFERROR(IF('1_INPUT_DATA'!B20="","", ('1_INPUT_DATA'!I20-'1_INPUT_DATA'!H20)*'1_INPUT_DATA'!D20*'1_INPUT_DATA'!F20),"") | H9: =IFERROR(IF('1_INPUT_DATA'!B20="","", E9-D9),"")
A10: =IFERROR(IF('1_INPUT_DATA'!A21="","",'1_INPUT_DATA'!A21),"") | B10: =IFERROR(IF('1_INPUT_DATA'!B21="","",'1_INPUT_DATA'!B21),"") | C10: =IFERROR(IF('1_INPUT_DATA'!C21="","",'1_INPUT_DATA'!C21),"") | D10: =IFERROR(IF('1_INPUT_DATA'!B21="","", '1_INPUT_DATA'!D21*'1_INPUT_DATA'!F21*(1+'1_INPUT_DATA'!H21)),"") | E10: =IFERROR(IF('1_INPUT_DATA'!B21="","", '1_INPUT_DATA'!D21*'1_INPUT_DATA'!G21*(1+'1_INPUT_DATA'!I21)),"") | F10: =IFERROR(IF('1_INPUT_DATA'!B21="","", ('1_INPUT_DATA'!G21-'1_INPUT_DATA'!F21)*'1_INPUT_DATA'!D21*(1+'1_INPUT_DATA'!I21)),"") | G10: =IFERROR(IF('1_INPUT_DATA'!B21="","", ('1_INPUT_DATA'!I21-'1_INPUT_DATA'!H21)*'1_INPUT_DATA'!D21*'1_INPUT_DATA'!F21),"") | H10: =IFERROR(IF('1_INPUT_DATA'!B21="","", E10-D10),"")
A11: =IFERROR(IF('1_INPUT_DATA'!A22="","",'1_INPUT_DATA'!A22),"") | B11: =IFERROR(IF('1_INPUT_DATA'!B22="","",'1_INPUT_DATA'!B22),"") | C11: =IFERROR(IF('1_INPUT_DATA'!C22="","",'1_INPUT_DATA'!C22),"") | D11: =IFERROR(IF('1_INPUT_DATA'!B22="","", '1_INPUT_DATA'!D22*'1_INPUT_DATA'!F22*(1+'1_INPUT_DATA'!H22)),"") | E11: =IFERROR(IF('1_INPUT_DATA'!B22="","", '1_INPUT_DATA'!D22*'1_INPUT_DATA'!G22*(1+'1_INPUT_DATA'!I22)),"") | F11: =IFERROR(IF('1_INPUT_DATA'!B22="","", ('1_INPUT_DATA'!G22-'1_INPUT_DATA'!F22)*'1_INPUT_DATA'!D22*(1+'1_INPUT_DATA'!I22)),"") | G11: =IFERROR(IF('1_INPUT_DATA'!B22="","", ('1_INPUT_DATA'!I22-'1_INPUT_DATA'!H22)*'1_INPUT_DATA'!D22*'1_INPUT_DATA'!F22),"") | H11: =IFERROR(IF('1_INPUT_DATA'!B22="","", E11-D11),"")
A12: =IFERROR(IF('1_INPUT_DATA'!A23="","",'1_INPUT_DATA'!A23),"") | B12: =IFERROR(IF('1_INPUT_DATA'!B23="","",'1_INPUT_DATA'!B23),"") | C12: =IFERROR(IF('1_INPUT_DATA'!C23="","",'1_INPUT_DATA'!C23),"") | D12: =IFERROR(IF('1_INPUT_DATA'!B23="","", '1_INPUT_DATA'!D23*'1_INPUT_DATA'!F23*(1+'1_INPUT_DATA'!H23)),"") | E12: =IFERROR(IF('1_INPUT_DATA'!B23="","", '1_INPUT_DATA'!D23*'1_INPUT_DATA'!G23*(1+'1_INPUT_DATA'!I23)),"") | F12: =IFERROR(IF('1_INPUT_DATA'!B23="","", ('1_INPUT_DATA'!G23-'1_INPUT_DATA'!F23)*'1_INPUT_DATA'!D23*(1+'1_INPUT_DATA'!I23)),"") | G12: =IFERROR(IF('1_INPUT_DATA'!B23="","", ('1_INPUT_DATA'!I23-'1_INPUT_DATA'!H23)*'1_INPUT_DATA'!D23*'1_INPUT_DATA'!F23),"") | H12: =IFERROR(IF('1_INPUT_DATA'!B23="","", E12-D12),"")
A13: =IFERROR(IF('1_INPUT_DATA'!A24="","",'1_INPUT_DATA'!A24),"") | B13: =IFERROR(IF('1_INPUT_DATA'!B24="","",'1_INPUT_DATA'!B24),"") | C13: =IFERROR(IF('1_INPUT_DATA'!C24="","",'1_INPUT_DATA'!C24),"") | D13: =IFERROR(IF('1_INPUT_DATA'!B24="","", '1_INPUT_DATA'!D24*'1_INPUT_DATA'!F24*(1+'1_INPUT_DATA'!H24)),"") | E13: =IFERROR(IF('1_INPUT_DATA'!B24="","", '1_INPUT_DATA'!D24*'1_INPUT_DATA'!G24*(1+'1_INPUT_DATA'!I24)),"") | F13: =IFERROR(IF('1_INPUT_DATA'!B24="","", ('1_INPUT_DATA'!G24-'1_INPUT_DATA'!F24)*'1_INPUT_DATA'!D24*(1+'1_INPUT_DATA'!I24)),"") | G13: =IFERROR(IF('1_INPUT_DATA'!B24="","", ('1_INPUT_DATA'!I24-'1_INPUT_DATA'!H24)*'1_INPUT_DATA'!D24*'1_INPUT_DATA'!F24),"") | H13: =IFERROR(IF('1_INPUT_DATA'!B24="","", E13-D13),"")
A14: =IFERROR(IF('1_INPUT_DATA'!A25="","",'1_INPUT_DATA'!A25),"") | B14: =IFERROR(IF('1_INPUT_DATA'!B25="","",'1_INPUT_DATA'!B25),"") | C14: =IFERROR(IF('1_INPUT_DATA'!C25="","",'1_INPUT_DATA'!C25),"") | D14: =IFERROR(IF('1_INPUT_DATA'!B25="","", '1_INPUT_DATA'!D25*'1_INPUT_DATA'!F25*(1+'1_INPUT_DATA'!H25)),"") | E14: =IFERROR(IF('1_INPUT_DATA'!B25="","", '1_INPUT_DATA'!D25*'1_INPUT_DATA'!G25*(1+'1_INPUT_DATA'!I25)),"") | F14: =IFERROR(IF('1_INPUT_DATA'!B25="","", ('1_INPUT_DATA'!G25-'1_INPUT_DATA'!F25)*'1_INPUT_DATA'!D25*(1+'1_INPUT_DATA'!I25)),"") | G14: =IFERROR(IF('1_INPUT_DATA'!B25="","", ('1_INPUT_DATA'!I25-'1_INPUT_DATA'!H25)*'1_INPUT_DATA'!D25*'1_INPUT_DATA'!F25),"") | H14: =IFERROR(IF('1_INPUT_DATA'!B25="","", E14-D14),"")
A15: =IFERROR(IF('1_INPUT_DATA'!A26="","",'1_INPUT_DATA'!A26),"") | B15: =IFERROR(IF('1_INPUT_DATA'!B26="","",'1_INPUT_DATA'!B26),"") | C15: =IFERROR(IF('1_INPUT_DATA'!C26="","",'1_INPUT_DATA'!C26),"") | D15: =IFERROR(IF('1_INPUT_DATA'!B26="","", '1_INPUT_DATA'!D26*'1_INPUT_DATA'!F26*(1+'1_INPUT_DATA'!H26)),"") | E15: =IFERROR(IF('1_INPUT_DATA'!B26="","", '1_INPUT_DATA'!D26*'1_INPUT_DATA'!G26*(1+'1_INPUT_DATA'!I26)),"") | F15: =IFERROR(IF('1_INPUT_DATA'!B26="","", ('1_INPUT_DATA'!G26-'1_INPUT_DATA'!F26)*'1_INPUT_DATA'!D26*(1+'1_INPUT_DATA'!I26)),"") | G15: =IFERROR(IF('1_INPUT_DATA'!B26="","", ('1_INPUT_DATA'!I26-'1_INPUT_DATA'!H26)*'1_INPUT_DATA'!D26*'1_INPUT_DATA'!F26),"") | H15: =IFERROR(IF('1_INPUT_DATA'!B26="","", E15-D15),"")
A16: TOTAL DIRECT MATERIAL (C_M) | D16: =IFERROR(SUM(D6:D15), 0) | E16: =IFERROR(SUM(E6:E15), 0) | F16: =IFERROR(SUM(F6:F15), 0) | G16: =IFERROR(SUM(G6:G15), 0) | H16: =IFERROR(SUM(H6:H15), 0)
A18: PART 2: CONVERSION PROCESS COST & VARIANCE (ROUTING)
A19: Seq (Op #) | B19: Process Name | C19: Work Center | D19: Base Runtime (MHr) | E19: Active Runtime (MHr) | F19: Base Labor (฿) | G19: Active Labor (฿) | H19: Base Burden (฿) | I19: Active Burden (฿) | J19: Active Process Cost (฿) | K19: Process Δ (฿)
A20: =IFERROR(IF('1_INPUT_DATA'!A30="","",'1_INPUT_DATA'!A30),"") | B20: =IFERROR(IF('1_INPUT_DATA'!B30="","",'1_INPUT_DATA'!B30),"") | C20: =IFERROR(IF('1_INPUT_DATA'!C30="","",'1_INPUT_DATA'!C30),"") | D20: =IFERROR(IF(OR('1_INPUT_DATA'!B30="", '1_INPUT_DATA'!E30="", '1_INPUT_DATA'!I30="", '1_INPUT_DATA'!E30=0, '1_INPUT_DATA'!I30=0), "", '1_INPUT_DATA'!D30/('1_INPUT_DATA'!E30*'1_INPUT_DATA'!I30)),"") | E20: =IFERROR(IF(OR('1_INPUT_DATA'!B30="", '1_INPUT_DATA'!F30="", '1_INPUT_DATA'!J30="", '1_INPUT_DATA'!F30=0, '1_INPUT_DATA'!J30=0), "", '1_INPUT_DATA'!D30/('1_INPUT_DATA'!F30*'1_INPUT_DATA'!J30)),"") | F20: =IFERROR(IF(OR('1_INPUT_DATA'!B30="", D20=""), "", D20*IFERROR(VLOOKUP('1_INPUT_DATA'!C30,'1_INPUT_DATA'!A$10:F$13,3,FALSE),0)),"") | G20: =IFERROR(IF(OR('1_INPUT_DATA'!B30="", E20=""), "", E20*IFERROR(VLOOKUP('1_INPUT_DATA'!C30,'1_INPUT_DATA'!A$10:F$13,3,FALSE),0)),"") | H20: =IFERROR(IF(OR('1_INPUT_DATA'!B30="", D20=""), "", D20*IFERROR(VLOOKUP('1_INPUT_DATA'!C30,'1_INPUT_DATA'!A$10:F$13,4,FALSE),0)),"") | I20: =IFERROR(IF(OR('1_INPUT_DATA'!B30="", E20=""), "", E20*IFERROR(VLOOKUP('1_INPUT_DATA'!C30,'1_INPUT_DATA'!A$10:F$13,4,FALSE),0)),"") | J20: =IFERROR(IF('1_INPUT_DATA'!B30="","", G20+I20),"") | K20: =IFERROR(IF('1_INPUT_DATA'!B30="","", J20-(F20+H20)),"")
A21: =IFERROR(IF('1_INPUT_DATA'!A31="","",'1_INPUT_DATA'!A31),"") | B21: =IFERROR(IF('1_INPUT_DATA'!B31="","",'1_INPUT_DATA'!B31),"") | C21: =IFERROR(IF('1_INPUT_DATA'!C31="","",'1_INPUT_DATA'!C31),"") | D21: =IFERROR(IF(OR('1_INPUT_DATA'!B31="", '1_INPUT_DATA'!E31="", '1_INPUT_DATA'!I31="", '1_INPUT_DATA'!E31=0, '1_INPUT_DATA'!I31=0), "", '1_INPUT_DATA'!D31/('1_INPUT_DATA'!E31*'1_INPUT_DATA'!I31)),"") | E21: =IFERROR(IF(OR('1_INPUT_DATA'!B31="", '1_INPUT_DATA'!F31="", '1_INPUT_DATA'!J31="", '1_INPUT_DATA'!F31=0, '1_INPUT_DATA'!J31=0), "", '1_INPUT_DATA'!D31/('1_INPUT_DATA'!F31*'1_INPUT_DATA'!J31)),"") | F21: =IFERROR(IF(OR('1_INPUT_DATA'!B31="", D21=""), "", D21*IFERROR(VLOOKUP('1_INPUT_DATA'!C31,'1_INPUT_DATA'!A$10:F$13,3,FALSE),0)),"") | G21: =IFERROR(IF(OR('1_INPUT_DATA'!B31="", E21=""), "", E21*IFERROR(VLOOKUP('1_INPUT_DATA'!C31,'1_INPUT_DATA'!A$10:F$13,3,FALSE),0)),"") | H21: =IFERROR(IF(OR('1_INPUT_DATA'!B31="", D21=""), "", D21*IFERROR(VLOOKUP('1_INPUT_DATA'!C31,'1_INPUT_DATA'!A$10:F$13,4,FALSE),0)),"") | I21: =IFERROR(IF(OR('1_INPUT_DATA'!B31="", E21=""), "", E21*IFERROR(VLOOKUP('1_INPUT_DATA'!C31,'1_INPUT_DATA'!A$10:F$13,4,FALSE),0)),"") | J21: =IFERROR(IF('1_INPUT_DATA'!B31="","", G21+I21),"") | K21: =IFERROR(IF('1_INPUT_DATA'!B31="","", J21-(F21+H21)),"")
A22: =IFERROR(IF('1_INPUT_DATA'!A32="","",'1_INPUT_DATA'!A32),"") | B22: =IFERROR(IF('1_INPUT_DATA'!B32="","",'1_INPUT_DATA'!B32),"") | C22: =IFERROR(IF('1_INPUT_DATA'!C32="","",'1_INPUT_DATA'!C32),"") | D22: =IFERROR(IF(OR('1_INPUT_DATA'!B32="", '1_INPUT_DATA'!E32="", '1_INPUT_DATA'!I32="", '1_INPUT_DATA'!E32=0, '1_INPUT_DATA'!I32=0), "", '1_INPUT_DATA'!D32/('1_INPUT_DATA'!E32*'1_INPUT_DATA'!I32)),"") | E22: =IFERROR(IF(OR('1_INPUT_DATA'!B32="", '1_INPUT_DATA'!F32="", '1_INPUT_DATA'!J32="", '1_INPUT_DATA'!F32=0, '1_INPUT_DATA'!J32=0), "", '1_INPUT_DATA'!D32/('1_INPUT_DATA'!F32*'1_INPUT_DATA'!J32)),"") | F22: =IFERROR(IF(OR('1_INPUT_DATA'!B32="", D22=""), "", D22*IFERROR(VLOOKUP('1_INPUT_DATA'!C32,'1_INPUT_DATA'!A$10:F$13,3,FALSE),0)),"") | G22: =IFERROR(IF(OR('1_INPUT_DATA'!B32="", E22=""), "", E22*IFERROR(VLOOKUP('1_INPUT_DATA'!C32,'1_INPUT_DATA'!A$10:F$13,3,FALSE),0)),"") | H22: =IFERROR(IF(OR('1_INPUT_DATA'!B32="", D22=""), "", D22*IFERROR(VLOOKUP('1_INPUT_DATA'!C32,'1_INPUT_DATA'!A$10:F$13,4,FALSE),0)),"") | I22: =IFERROR(IF(OR('1_INPUT_DATA'!B32="", E22=""), "", E22*IFERROR(VLOOKUP('1_INPUT_DATA'!C32,'1_INPUT_DATA'!A$10:F$13,4,FALSE),0)),"") | J22: =IFERROR(IF('1_INPUT_DATA'!B32="","", G22+I22),"") | K22: =IFERROR(IF('1_INPUT_DATA'!B32="","", J22-(F22+H22)),"")
A23: =IFERROR(IF('1_INPUT_DATA'!A33="","",'1_INPUT_DATA'!A33),"") | B23: =IFERROR(IF('1_INPUT_DATA'!B33="","",'1_INPUT_DATA'!B33),"") | C23: =IFERROR(IF('1_INPUT_DATA'!C33="","",'1_INPUT_DATA'!C33),"") | D23: =IFERROR(IF(OR('1_INPUT_DATA'!B33="", '1_INPUT_DATA'!E33="", '1_INPUT_DATA'!I33="", '1_INPUT_DATA'!E33=0, '1_INPUT_DATA'!I33=0), "", '1_INPUT_DATA'!D33/('1_INPUT_DATA'!E33*'1_INPUT_DATA'!I33)),"") | E23: =IFERROR(IF(OR('1_INPUT_DATA'!B33="", '1_INPUT_DATA'!F33="", '1_INPUT_DATA'!J33="", '1_INPUT_DATA'!F33=0, '1_INPUT_DATA'!J33=0), "", '1_INPUT_DATA'!D33/('1_INPUT_DATA'!F33*'1_INPUT_DATA'!J33)),"") | F23: =IFERROR(IF(OR('1_INPUT_DATA'!B33="", D23=""), "", D23*IFERROR(VLOOKUP('1_INPUT_DATA'!C33,'1_INPUT_DATA'!A$10:F$13,3,FALSE),0)),"") | G23: =IFERROR(IF(OR('1_INPUT_DATA'!B33="", E23=""), "", E23*IFERROR(VLOOKUP('1_INPUT_DATA'!C33,'1_INPUT_DATA'!A$10:F$13,3,FALSE),0)),"") | H23: =IFERROR(IF(OR('1_INPUT_DATA'!B33="", D23=""), "", D23*IFERROR(VLOOKUP('1_INPUT_DATA'!C33,'1_INPUT_DATA'!A$10:F$13,4,FALSE),0)),"") | I23: =IFERROR(IF(OR('1_INPUT_DATA'!B33="", E23=""), "", E23*IFERROR(VLOOKUP('1_INPUT_DATA'!C33,'1_INPUT_DATA'!A$10:F$13,4,FALSE),0)),"") | J23: =IFERROR(IF('1_INPUT_DATA'!B33="","", G23+I23),"") | K23: =IFERROR(IF('1_INPUT_DATA'!B33="","", J23-(F23+H23)),"")
A24: =IFERROR(IF('1_INPUT_DATA'!A34="","",'1_INPUT_DATA'!A34),"") | B24: =IFERROR(IF('1_INPUT_DATA'!B34="","",'1_INPUT_DATA'!B34),"") | C24: =IFERROR(IF('1_INPUT_DATA'!C34="","",'1_INPUT_DATA'!C34),"") | D24: =IFERROR(IF(OR('1_INPUT_DATA'!B34="", '1_INPUT_DATA'!E34="", '1_INPUT_DATA'!I34="", '1_INPUT_DATA'!E34=0, '1_INPUT_DATA'!I34=0), "", '1_INPUT_DATA'!D34/('1_INPUT_DATA'!E34*'1_INPUT_DATA'!I34)),"") | E24: =IFERROR(IF(OR('1_INPUT_DATA'!B34="", '1_INPUT_DATA'!F34="", '1_INPUT_DATA'!J34="", '1_INPUT_DATA'!F34=0, '1_INPUT_DATA'!J34=0), "", '1_INPUT_DATA'!D34/('1_INPUT_DATA'!F34*'1_INPUT_DATA'!J34)),"") | F24: =IFERROR(IF(OR('1_INPUT_DATA'!B34="", D24=""), "", D24*IFERROR(VLOOKUP('1_INPUT_DATA'!C34,'1_INPUT_DATA'!A$10:F$13,3,FALSE),0)),"") | G24: =IFERROR(IF(OR('1_INPUT_DATA'!B34="", E24=""), "", E24*IFERROR(VLOOKUP('1_INPUT_DATA'!C34,'1_INPUT_DATA'!A$10:F$13,3,FALSE),0)),"") | H24: =IFERROR(IF(OR('1_INPUT_DATA'!B34="", D24=""), "", D24*IFERROR(VLOOKUP('1_INPUT_DATA'!C34,'1_INPUT_DATA'!A$10:F$13,4,FALSE),0)),"") | I24: =IFERROR(IF(OR('1_INPUT_DATA'!B34="", E24=""), "", E24*IFERROR(VLOOKUP('1_INPUT_DATA'!C34,'1_INPUT_DATA'!A$10:F$13,4,FALSE),0)),"") | J24: =IFERROR(IF('1_INPUT_DATA'!B34="","", G24+I24),"") | K24: =IFERROR(IF('1_INPUT_DATA'!B34="","", J24-(F24+H24)),"")
A25: =IFERROR(IF('1_INPUT_DATA'!A35="","",'1_INPUT_DATA'!A35),"") | B25: =IFERROR(IF('1_INPUT_DATA'!B35="","",'1_INPUT_DATA'!B35),"") | C25: =IFERROR(IF('1_INPUT_DATA'!C35="","",'1_INPUT_DATA'!C35),"") | D25: =IFERROR(IF(OR('1_INPUT_DATA'!B35="", '1_INPUT_DATA'!E35="", '1_INPUT_DATA'!I35="", '1_INPUT_DATA'!E35=0, '1_INPUT_DATA'!I35=0), "", '1_INPUT_DATA'!D35/('1_INPUT_DATA'!E35*'1_INPUT_DATA'!I35)),"") | E25: =IFERROR(IF(OR('1_INPUT_DATA'!B35="", '1_INPUT_DATA'!F35="", '1_INPUT_DATA'!J35="", '1_INPUT_DATA'!F35=0, '1_INPUT_DATA'!J35=0), "", '1_INPUT_DATA'!D35/('1_INPUT_DATA'!F35*'1_INPUT_DATA'!J35)),"") | F25: =IFERROR(IF(OR('1_INPUT_DATA'!B35="", D25=""), "", D25*IFERROR(VLOOKUP('1_INPUT_DATA'!C35,'1_INPUT_DATA'!A$10:F$13,3,FALSE),0)),"") | G25: =IFERROR(IF(OR('1_INPUT_DATA'!B35="", E25=""), "", E25*IFERROR(VLOOKUP('1_INPUT_DATA'!C35,'1_INPUT_DATA'!A$10:F$13,3,FALSE),0)),"") | H25: =IFERROR(IF(OR('1_INPUT_DATA'!B35="", D25=""), "", D25*IFERROR(VLOOKUP('1_INPUT_DATA'!C35,'1_INPUT_DATA'!A$10:F$13,4,FALSE),0)),"") | I25: =IFERROR(IF(OR('1_INPUT_DATA'!B35="", E25=""), "", E25*IFERROR(VLOOKUP('1_INPUT_DATA'!C35,'1_INPUT_DATA'!A$10:F$13,4,FALSE),0)),"") | J25: =IFERROR(IF('1_INPUT_DATA'!B35="","", G25+I25),"") | K25: =IFERROR(IF('1_INPUT_DATA'!B35="","", J25-(F25+H25)),"")
A26: =IFERROR(IF('1_INPUT_DATA'!A36="","",'1_INPUT_DATA'!A36),"") | B26: =IFERROR(IF('1_INPUT_DATA'!B36="","",'1_INPUT_DATA'!B36),"") | C26: =IFERROR(IF('1_INPUT_DATA'!C36="","",'1_INPUT_DATA'!C36),"") | D26: =IFERROR(IF(OR('1_INPUT_DATA'!B36="", '1_INPUT_DATA'!E36="", '1_INPUT_DATA'!I36="", '1_INPUT_DATA'!E36=0, '1_INPUT_DATA'!I36=0), "", '1_INPUT_DATA'!D36/('1_INPUT_DATA'!E36*'1_INPUT_DATA'!I36)),"") | E26: =IFERROR(IF(OR('1_INPUT_DATA'!B36="", '1_INPUT_DATA'!F36="", '1_INPUT_DATA'!J36="", '1_INPUT_DATA'!F36=0, '1_INPUT_DATA'!J36=0), "", '1_INPUT_DATA'!D36/('1_INPUT_DATA'!F36*'1_INPUT_DATA'!J36)),"") | F26: =IFERROR(IF(OR('1_INPUT_DATA'!B36="", D26=""), "", D26*IFERROR(VLOOKUP('1_INPUT_DATA'!C36,'1_INPUT_DATA'!A$10:F$13,3,FALSE),0)),"") | G26: =IFERROR(IF(OR('1_INPUT_DATA'!B36="", E26=""), "", E26*IFERROR(VLOOKUP('1_INPUT_DATA'!C36,'1_INPUT_DATA'!A$10:F$13,3,FALSE),0)),"") | H26: =IFERROR(IF(OR('1_INPUT_DATA'!B36="", D26=""), "", D26*IFERROR(VLOOKUP('1_INPUT_DATA'!C36,'1_INPUT_DATA'!A$10:F$13,4,FALSE),0)),"") | I26: =IFERROR(IF(OR('1_INPUT_DATA'!B36="", E26=""), "", E26*IFERROR(VLOOKUP('1_INPUT_DATA'!C36,'1_INPUT_DATA'!A$10:F$13,4,FALSE),0)),"") | J26: =IFERROR(IF('1_INPUT_DATA'!B36="","", G26+I26),"") | K26: =IFERROR(IF('1_INPUT_DATA'!B36="","", J26-(F26+H26)),"")
A27: =IFERROR(IF('1_INPUT_DATA'!A37="","",'1_INPUT_DATA'!A37),"") | B27: =IFERROR(IF('1_INPUT_DATA'!B37="","",'1_INPUT_DATA'!B37),"") | C27: =IFERROR(IF('1_INPUT_DATA'!C37="","",'1_INPUT_DATA'!C37),"") | D27: =IFERROR(IF(OR('1_INPUT_DATA'!B37="", '1_INPUT_DATA'!E37="", '1_INPUT_DATA'!I37="", '1_INPUT_DATA'!E37=0, '1_INPUT_DATA'!I37=0), "", '1_INPUT_DATA'!D37/('1_INPUT_DATA'!E37*'1_INPUT_DATA'!I37)),"") | E27: =IFERROR(IF(OR('1_INPUT_DATA'!B37="", '1_INPUT_DATA'!F37="", '1_INPUT_DATA'!J37="", '1_INPUT_DATA'!F37=0, '1_INPUT_DATA'!J37=0), "", '1_INPUT_DATA'!D37/('1_INPUT_DATA'!F37*'1_INPUT_DATA'!J37)),"") | F27: =IFERROR(IF(OR('1_INPUT_DATA'!B37="", D27=""), "", D27*IFERROR(VLOOKUP('1_INPUT_DATA'!C37,'1_INPUT_DATA'!A$10:F$13,3,FALSE),0)),"") | G27: =IFERROR(IF(OR('1_INPUT_DATA'!B37="", E27=""), "", E27*IFERROR(VLOOKUP('1_INPUT_DATA'!C37,'1_INPUT_DATA'!A$10:F$13,3,FALSE),0)),"") | H27: =IFERROR(IF(OR('1_INPUT_DATA'!B37="", D27=""), "", D27*IFERROR(VLOOKUP('1_INPUT_DATA'!C37,'1_INPUT_DATA'!A$10:F$13,4,FALSE),0)),"") | I27: =IFERROR(IF(OR('1_INPUT_DATA'!B37="", E27=""), "", E27*IFERROR(VLOOKUP('1_INPUT_DATA'!C37,'1_INPUT_DATA'!A$10:F$13,4,FALSE),0)),"") | J27: =IFERROR(IF('1_INPUT_DATA'!B37="","", G27+I27),"") | K27: =IFERROR(IF('1_INPUT_DATA'!B37="","", J27-(F27+H27)),"")
A28: =IFERROR(IF('1_INPUT_DATA'!A38="","",'1_INPUT_DATA'!A38),"") | B28: =IFERROR(IF('1_INPUT_DATA'!B38="","",'1_INPUT_DATA'!B38),"") | C28: =IFERROR(IF('1_INPUT_DATA'!C38="","",'1_INPUT_DATA'!C38),"") | D28: =IFERROR(IF(OR('1_INPUT_DATA'!B38="", '1_INPUT_DATA'!E38="", '1_INPUT_DATA'!I38="", '1_INPUT_DATA'!E38=0, '1_INPUT_DATA'!I38=0), "", '1_INPUT_DATA'!D38/('1_INPUT_DATA'!E38*'1_INPUT_DATA'!I38)),"") | E28: =IFERROR(IF(OR('1_INPUT_DATA'!B38="", '1_INPUT_DATA'!F38="", '1_INPUT_DATA'!J38="", '1_INPUT_DATA'!F38=0, '1_INPUT_DATA'!J38=0), "", '1_INPUT_DATA'!D38/('1_INPUT_DATA'!F38*'1_INPUT_DATA'!J38)),"") | F28: =IFERROR(IF(OR('1_INPUT_DATA'!B38="", D28=""), "", D28*IFERROR(VLOOKUP('1_INPUT_DATA'!C38,'1_INPUT_DATA'!A$10:F$13,3,FALSE),0)),"") | G28: =IFERROR(IF(OR('1_INPUT_DATA'!B38="", E28=""), "", E28*IFERROR(VLOOKUP('1_INPUT_DATA'!C38,'1_INPUT_DATA'!A$10:F$13,3,FALSE),0)),"") | H28: =IFERROR(IF(OR('1_INPUT_DATA'!B38="", D28=""), "", D28*IFERROR(VLOOKUP('1_INPUT_DATA'!C38,'1_INPUT_DATA'!A$10:F$13,4,FALSE),0)),"") | I28: =IFERROR(IF(OR('1_INPUT_DATA'!B38="", E28=""), "", E28*IFERROR(VLOOKUP('1_INPUT_DATA'!C38,'1_INPUT_DATA'!A$10:F$13,4,FALSE),0)),"") | J28: =IFERROR(IF('1_INPUT_DATA'!B38="","", G28+I28),"") | K28: =IFERROR(IF('1_INPUT_DATA'!B38="","", J28-(F28+H28)),"")
A29: =IFERROR(IF('1_INPUT_DATA'!A39="","",'1_INPUT_DATA'!A39),"") | B29: =IFERROR(IF('1_INPUT_DATA'!B39="","",'1_INPUT_DATA'!B39),"") | C29: =IFERROR(IF('1_INPUT_DATA'!C39="","",'1_INPUT_DATA'!C39),"") | D29: =IFERROR(IF(OR('1_INPUT_DATA'!B39="", '1_INPUT_DATA'!E39="", '1_INPUT_DATA'!I39="", '1_INPUT_DATA'!E39=0, '1_INPUT_DATA'!I39=0), "", '1_INPUT_DATA'!D39/('1_INPUT_DATA'!E39*'1_INPUT_DATA'!I39)),"") | E29: =IFERROR(IF(OR('1_INPUT_DATA'!B39="", '1_INPUT_DATA'!F39="", '1_INPUT_DATA'!J39="", '1_INPUT_DATA'!F39=0, '1_INPUT_DATA'!J39=0), "", '1_INPUT_DATA'!D39/('1_INPUT_DATA'!F39*'1_INPUT_DATA'!J39)),"") | F29: =IFERROR(IF(OR('1_INPUT_DATA'!B39="", D29=""), "", D29*IFERROR(VLOOKUP('1_INPUT_DATA'!C39,'1_INPUT_DATA'!A$10:F$13,3,FALSE),0)),"") | G29: =IFERROR(IF(OR('1_INPUT_DATA'!B39="", E29=""), "", E29*IFERROR(VLOOKUP('1_INPUT_DATA'!C39,'1_INPUT_DATA'!A$10:F$13,3,FALSE),0)),"") | H29: =IFERROR(IF(OR('1_INPUT_DATA'!B39="", D29=""), "", D29*IFERROR(VLOOKUP('1_INPUT_DATA'!C39,'1_INPUT_DATA'!A$10:F$13,4,FALSE),0)),"") | I29: =IFERROR(IF(OR('1_INPUT_DATA'!B39="", E29=""), "", E29*IFERROR(VLOOKUP('1_INPUT_DATA'!C39,'1_INPUT_DATA'!A$10:F$13,4,FALSE),0)),"") | J29: =IFERROR(IF('1_INPUT_DATA'!B39="","", G29+I29),"") | K29: =IFERROR(IF('1_INPUT_DATA'!B39="","", J29-(F29+H29)),"")
A30: =IFERROR(IF('1_INPUT_DATA'!A40="","",'1_INPUT_DATA'!A40),"") | B30: =IFERROR(IF('1_INPUT_DATA'!B40="","",'1_INPUT_DATA'!B40),"") | C30: =IFERROR(IF('1_INPUT_DATA'!C40="","",'1_INPUT_DATA'!C40),"") | D30: =IFERROR(IF(OR('1_INPUT_DATA'!B40="", '1_INPUT_DATA'!E40="", '1_INPUT_DATA'!I40="", '1_INPUT_DATA'!E40=0, '1_INPUT_DATA'!I40=0), "", '1_INPUT_DATA'!D40/('1_INPUT_DATA'!E40*'1_INPUT_DATA'!I40)),"") | E30: =IFERROR(IF(OR('1_INPUT_DATA'!B40="", '1_INPUT_DATA'!F40="", '1_INPUT_DATA'!J40="", '1_INPUT_DATA'!F40=0, '1_INPUT_DATA'!J40=0), "", '1_INPUT_DATA'!D40/('1_INPUT_DATA'!F40*'1_INPUT_DATA'!J40)),"") | F30: =IFERROR(IF(OR('1_INPUT_DATA'!B40="", D30=""), "", D30*IFERROR(VLOOKUP('1_INPUT_DATA'!C40,'1_INPUT_DATA'!A$10:F$13,3,FALSE),0)),"") | G30: =IFERROR(IF(OR('1_INPUT_DATA'!B40="", E30=""), "", E30*IFERROR(VLOOKUP('1_INPUT_DATA'!C40,'1_INPUT_DATA'!A$10:F$13,3,FALSE),0)),"") | H30: =IFERROR(IF(OR('1_INPUT_DATA'!B40="", D30=""), "", D30*IFERROR(VLOOKUP('1_INPUT_DATA'!C40,'1_INPUT_DATA'!A$10:F$13,4,FALSE),0)),"") | I30: =IFERROR(IF(OR('1_INPUT_DATA'!B40="", E30=""), "", E30*IFERROR(VLOOKUP('1_INPUT_DATA'!C40,'1_INPUT_DATA'!A$10:F$13,4,FALSE),0)),"") | J30: =IFERROR(IF('1_INPUT_DATA'!B40="","", G30+I30),"") | K30: =IFERROR(IF('1_INPUT_DATA'!B40="","", J30-(F30+H30)),"")
A31: =IFERROR(IF('1_INPUT_DATA'!A41="","",'1_INPUT_DATA'!A41),"") | B31: =IFERROR(IF('1_INPUT_DATA'!B41="","",'1_INPUT_DATA'!B41),"") | C31: =IFERROR(IF('1_INPUT_DATA'!C41="","",'1_INPUT_DATA'!C41),"") | D31: =IFERROR(IF(OR('1_INPUT_DATA'!B41="", '1_INPUT_DATA'!E41="", '1_INPUT_DATA'!I41="", '1_INPUT_DATA'!E41=0, '1_INPUT_DATA'!I41=0), "", '1_INPUT_DATA'!D41/('1_INPUT_DATA'!E41*'1_INPUT_DATA'!I41)),"") | E31: =IFERROR(IF(OR('1_INPUT_DATA'!B41="", '1_INPUT_DATA'!F41="", '1_INPUT_DATA'!J41="", '1_INPUT_DATA'!F41=0, '1_INPUT_DATA'!J41=0), "", '1_INPUT_DATA'!D41/('1_INPUT_DATA'!F41*'1_INPUT_DATA'!J41)),"") | F31: =IFERROR(IF(OR('1_INPUT_DATA'!B41="", D31=""), "", D31*IFERROR(VLOOKUP('1_INPUT_DATA'!C41,'1_INPUT_DATA'!A$10:F$13,3,FALSE),0)),"") | G31: =IFERROR(IF(OR('1_INPUT_DATA'!B41="", E31=""), "", E31*IFERROR(VLOOKUP('1_INPUT_DATA'!C41,'1_INPUT_DATA'!A$10:F$13,3,FALSE),0)),"") | H31: =IFERROR(IF(OR('1_INPUT_DATA'!B41="", D31=""), "", D31*IFERROR(VLOOKUP('1_INPUT_DATA'!C41,'1_INPUT_DATA'!A$10:F$13,4,FALSE),0)),"") | I31: =IFERROR(IF(OR('1_INPUT_DATA'!B41="", E31=""), "", E31*IFERROR(VLOOKUP('1_INPUT_DATA'!C41,'1_INPUT_DATA'!A$10:F$13,4,FALSE),0)),"") | J31: =IFERROR(IF('1_INPUT_DATA'!B41="","", G31+I31),"") | K31: =IFERROR(IF('1_INPUT_DATA'!B41="","", J31-(F31+H31)),"")
A32: TOTAL CONVERSION PROCESS (C_L + C_B) | F32: =IFERROR(SUM(F20:F31), 0) | G32: =IFERROR(SUM(G20:G31), 0) | H32: =IFERROR(SUM(H20:H31), 0) | I32: =IFERROR(SUM(I20:I31), 0) | J32: =IFERROR(SUM(J20:J31), 0) | K32: =IFERROR(SUM(K20:K31), 0)
A34: PART 3: 3-PILLAR COST ROLL-UP (REFERENCE VS. CURRENT STANDARD)
A35: Cost Element | B35: Baseline Reference Std (฿/pc) | C35: Active Current Std (฿/pc) | D35: Post-Kaizen Std (฿/pc) | E35: Total Variance (Δ ฿/pc) | F35: % Variance | G35: Primary Root Cause Driver
A36: Direct Material Cost (C_M) | B36: =IFERROR(D16, 0) | C36: =IFERROR(E16, 0) | D36: =IFERROR(E16, 0) | E36: =IFERROR(C36-B36, 0) | F36: =IFERROR(IF(B36>0,E36/B36,0), 0) | G36: Direct Material Inflation Driver
A37: Direct Labor Cost (C_L) | B37: =IFERROR(F32, 0) | C37: =IFERROR(G32, 0) | D37: =IFERROR(G32, 0) | E37: =IFERROR(C37-B37, 0) | F37: =IFERROR(IF(B37>0,E37/B37,0), 0) | G37: Direct Labor Conversion Driver
A38: Manufacturing Burden (C_B) | B38: =IFERROR(H32, 0) | C38: =IFERROR(I32, 0) | D38: =IFERROR(I32, 0) | E38: =IFERROR(C38-B38, 0) | F38: =IFERROR(IF(B38>0,E38/B38,0), 0) | G38: Manufacturing Overhead Driver
A39: Total Standard Cost (C_Total) | B39: =IFERROR(SUM(B36:B38), 0) | C39: =IFERROR(SUM(C36:C38), 0) | D39: =IFERROR(SUM(D36:D38), 0) | E39: =IFERROR(C39-B39, 0) | F39: =IFERROR(IF(B39>0,E39/B39,0), 0) | G39: Standard Cost Roll-up Benchmark
A41: LEVEL 3: ATOMIC VARIANCE DECOMPOSITION & RECONCILIATION
A42: Variance Decomposition Branch | B42: Cost Variance (THB/pc) | C42: % Contribution | D42: Variance Type | E42: Accountability
A43: Level 0: Total Standard Variance (Δ C_Total) | B43: =IFERROR(E39, 0) | C43: =IFERROR(IF(B43<>0,B43/B43,0),0) | D43: Net Inflation Gap | E43: Overall Plant
A44: ├── Material Price Variance (MPV) | B44: =IFERROR(F16, 0) | C44: =IFERROR(IF(B$43<>0,B44/B$43,0),0) | D44: Market Price Inflation | E44: Purchasing
...

Sheet 3_EXECUTIVE_SUMMARY
A1: EXECUTIVE SUMMARY & COST BRIDGE
A2: Standard Cost Gap Bridge & Strategic Kaizen Candidate Ranking
A4: 1. COST BRIDGE SUMMARY (THB / pc)
A5: Step | B5: Cost Stage / Driver | C5: Cost (฿/pc) | D5: Variance (Δ ฿) | E5: % Total Cost | F5: Waterfall Step Type
A6: 0 | B6: Baseline Reference Standard Cost | C6: =IFERROR('2_COST_BREAKDOWN'!B39, 0) | D6: - | E6: =IFERROR(IF('2_COST_BREAKDOWN'!B39>0,'2_COST_BREAKDOWN'!B39/'2_COST_BREAKDOWN'!B39,0),0) | F6: Starting Baseline
A7: +1 | B7: Direct Material Price Inflation (MPV) | C7: =IFERROR('2_COST_BREAKDOWN'!F16, 0) | D7: =IFERROR('2_COST_BREAKDOWN'!F16, 0) | E7: =IFERROR(IF('2_COST_BREAKDOWN'!B39>0,'2_COST_BREAKDOWN'!F16/'2_COST_BREAKDOWN'!B39,0),0) | F7: Market Escalation
A8: +2 | B8: Direct Labor Conversion Gap (LRV+LEV) | C8: =IFERROR('2_COST_BREAKDOWN'!E37, 0) | D8: =IFERROR('2_COST_BREAKDOWN'!E37, 0) | E8: =IFERROR(IF('2_COST_BREAKDOWN'!B39>0,'2_COST_BREAKDOWN'!E37/'2_COST_BREAKDOWN'!B39,0),0) | F8: Process Yield Drop
A9: +3 | B9: Manufacturing Burden Gap (BRV+BEV) | C9: =IFERROR('2_COST_BREAKDOWN'!E38, 0) | D9: =IFERROR('2_COST_BREAKDOWN'!E38, 0) | E9: =IFERROR(IF('2_COST_BREAKDOWN'!B39>0,'2_COST_BREAKDOWN'!E38/'2_COST_BREAKDOWN'!B39,0),0) | F9: Machine Extended Runtime
A10: = | B10: Active Current Standard Cost | C10: =IFERROR('2_COST_BREAKDOWN'!C39, 0) | D10: =IFERROR('2_COST_BREAKDOWN'!E39, 0) | E10: =IFERROR(IF('2_COST_BREAKDOWN'!B39>0,'2_COST_BREAKDOWN'!C39/'2_COST_BREAKDOWN'!B39,0),0) | F10: Active Benchmark
A11: ★ | B11: Target Post-Kaizen Standard Cost (Option A) | C11: =IFERROR('4_WHAT_IF_SIMULATOR'!I12, "") | D11: =IFERROR(IF('4_WHAT_IF_SIMULATOR'!I12<>"",'4_WHAT_IF_SIMULATOR'!I12-'2_COST_BREAKDOWN'!B39,0),0) | E11: =IFERROR(IF(AND('2_COST_BREAKDOWN'!B39>0,'4_WHAT_IF_SIMULATOR'!I12<>""),'4_WHAT_IF_SIMULATOR'!I12/'2_COST_BREAKDOWN'!B39,0),0) | F11: Future Standard Target
A13: 2. COST GAP RANKING & KAIZEN CANDIDATE SELECTION
A14: Rank | B14: Cost Driver Item | C14: Category | D14: Baseline Reference | E14: Active Standard | F14: Cost Gap (Δ ฿/pc) | G14: Controllability | H14: Ownership / Action Department
A15: #1 | B15: Direct Material Price Inflation | C15: Direct Material (BOM) | D15: =IFERROR(IF('1_INPUT_DATA'!F17="","",'1_INPUT_DATA'!F17),"") | E15: =IFERROR(IF('1_INPUT_DATA'!G17="","",'1_INPUT_DATA'!G17),"") | F15: =IFERROR('2_COST_BREAKDOWN'!F16, 0) | G15: Uncontrollable (Market Index) | H15: Purchasing Department
A16: #2 | B16: Process Yield Efficiency Gap | C16: Process Routing | D16: =IFERROR(IF('1_INPUT_DATA'!I33="","",'1_INPUT_DATA'!I33),"") | E16: =IFERROR(IF('1_INPUT_DATA'!J33="","",'1_INPUT_DATA'!J33),"") | F16: =IFERROR('2_COST_BREAKDOWN'!K23+'2_COST_BREAKDOWN'!K25, 0) | G16: ⭐ 100% Controllable (Kaizen Target) | H16: IE / Cleanroom Production
A17: #3 | B17: Manufacturing Overhead Gap | C17: Machine Burden | D17: =IFERROR(IF('1_INPUT_DATA'!D10="","",'1_INPUT_DATA'!D10),"") | E17: =IFERROR(IF('1_INPUT_DATA'!D10="","",'1_INPUT_DATA'!D10),"") | F17: =IFERROR('2_COST_BREAKDOWN'!E38, 0) | G17: Uncontrollable (Fixed Index) | H17: Accounting & Finance

Sheet 4_WHAT_IF_SIMULATOR
A1: RCA & DYNAMIC WHAT-IF SIMULATION ENGINE
A2: Enter factory investment and target parameter. System automatically computes per-unit savings and new standard cost.
A4: 1. ROOT CAUSE ANALYSIS (RCA) DIAGNOSIS (Target Operational Parameter)
A5: Target Factor
A6: Current State
A7: RCA Question
A8: Root Cause
A10: 2. MULTI-OPTION KAIZEN SIMULATION & TRADE-OFF COMPARISON
A11: Option | B11: Action / Countermeasure | C11: Target Yield | D11: Investment (฿) | E11: Lot Size (pcs) | F11: Added Cost (฿/pc) | G11: Gross Saving (฿/pc) | H11: Net Saving (฿/pc) | I11: Predicted Cost (฿/pc) | J11: Profitability Indicator
A12: A | F12: =IFERROR(IF(OR(D12="",E12="",E12=0),"", D12/E12),"") | G12: =IFERROR(IF(OR(C12="",C12=0),"", ('2_COST_BREAKDOWN'!J23+'2_COST_BREAKDOWN'!J25)*(1-IF('1_INPUT_DATA'!J33<>"",'1_INPUT_DATA'!J33/C12,0.9/C12))),"") | H12: =IFERROR(IF(OR(F12="",G12=""),"", G12-F12),"") | I12: =IFERROR(IF(H12="","", '2_COST_BREAKDOWN'!C39-H12), "") | J12: =IFERROR(IF(H12="","", IF(H12>0,"⭐ Profitable","❌ Loss")),"")
A13: B | F13: =IFERROR(IF(OR(D13="",E13="",E13=0),"", D13/E13),"") | G13: =IFERROR(IF(OR(C13="",C13=0),"", ('2_COST_BREAKDOWN'!J23+'2_COST_BREAKDOWN'!J25)*(1-IF('1_INPUT_DATA'!J33<>"",'1_INPUT_DATA'!J33/C13,0.9/C13))),"") | H13: =IFERROR(IF(OR(F13="",G13=""),"", G13-F13),"") | I13: =IFERROR(IF(H13="","", '2_COST_BREAKDOWN'!C39-H13), "") | J13: =IFERROR(IF(H13="","", IF(H13>0,"⭐ Profitable","❌ Loss")),"")
A14: C | F14: =IFERROR(IF(OR(D14="",E14="",E14=0),"", D14/E14),"") | G14: =IFERROR(IF(OR(C14="",C14=0),"", ('2_COST_BREAKDOWN'!J23+'2_COST_BREAKDOWN'!J25)*(1-IF('1_INPUT_DATA'!J33<>"",'1_INPUT_DATA'!J33/C14,0.9/C14))),"") | H14: =IFERROR(IF(OR(F14="",G14=""),"", G14-F14),"") | I14: =IFERROR(IF(H14="","", '2_COST_BREAKDOWN'!C39-H14), "") | J14: =IFERROR(IF(H14="","", IF(H14>0,"⭐ Profitable","❌ Loss")),"")
