Workbook

Sheet 1_MASTER_RATES
A1: PRODUCT INFO & WORK CENTER RATES
A3: PRODUCT INFO
A4: Product Name | B4: Product Code | C4: Description | D4: UOM | E4: Source Reference
A7: WORK CENTER RATES
A8: Department | B8: Labor Rate (THB/MHr) | C8: Burden Rate (THB/MHr) | D8: Effective Date | E8: Source Reference

Sheet 2_BOM_BREAKDOWN
A1: DIRECT MATERIAL COST BREAKDOWN (BOM)
A3: BOM INPUT DATA
A4: Item No | B4: Material Code | C4: Material Description | D4: Consumption | E4: UOM | F4: Base Price (THB) | G4: Active Price (THB) | H4: Base Loss (%) | I4: Active Loss (%) | J4: Source Reference
A22: BOM COST CALCULATION & VARIANCE
A23: Item No | B23: Material Code | C23: Material Description | D23: Base Cost (THB) | E23: Active Cost (THB) | F23: Price Var (THB) | G23: Loss Var (THB) | H23: Total Mat Var (Δ THB)
A24: =IFERROR(IF(A5="","",A5),"") | B24: =IFERROR(IF(B5="","",B5),"") | C24: =IFERROR(IF(C5="","",C5),"") | D24: =IFERROR(IF(OR(D5="", F5="", H5="", H5>=1), "", (D5*F5)/(1-H5)), "") | E24: =IFERROR(IF(OR(D5="", G5="", I5="", I5>=1), "", (D5*G5)/(1-I5)), "") | F24: =IFERROR(IF(OR(D5="", F5="", G5="", H5="", H5>=1, D24=""), "", ((D5*G5)/(1-H5))-D24), "") | G24: =IFERROR(IF(OR(D5="", G5="", H5="", I5="", H5>=1, I5>=1, E24=""), "", E24-((D5*G5)/(1-H5))), "") | H24: =IFERROR(IF(OR(D24="", E24=""), "", E24-D24), "")
A25: =IFERROR(IF(A6="","",A6),"") | B25: =IFERROR(IF(B6="","",B6),"") | C25: =IFERROR(IF(C6="","",C6),"") | D25: =IFERROR(IF(OR(D6="", F6="", H6="", H6>=1), "", (D6*F6)/(1-H6)), "") | E25: =IFERROR(IF(OR(D6="", G6="", I6="", I6>=1), "", (D6*G6)/(1-I6)), "") | F25: =IFERROR(IF(OR(D6="", F6="", G6="", H6="", H6>=1, D25=""), "", ((D6*G6)/(1-H6))-D25), "") | G25: =IFERROR(IF(OR(D6="", G6="", H6="", I6="", H6>=1, I6>=1, E25=""), "", E25-((D6*G6)/(1-H6))), "") | H25: =IFERROR(IF(OR(D25="", E25=""), "", E25-D25), "")
A26: =IFERROR(IF(A7="","",A7),"") | B26: =IFERROR(IF(B7="","",B7),"") | C26: =IFERROR(IF(C7="","",C7),"") | D26: =IFERROR(IF(OR(D7="", F7="", H7="", H7>=1), "", (D7*F7)/(1-H7)), "") | E26: =IFERROR(IF(OR(D7="", G7="", I7="", I7>=1), "", (D7*G7)/(1-I7)), "") | F26: =IFERROR(IF(OR(D7="", F7="", G7="", H7="", H7>=1, D26=""), "", ((D7*G7)/(1-H7))-D26), "") | G26: =IFERROR(IF(OR(D7="", G7="", H7="", I7="", H7>=1, I7>=1, E26=""), "", E26-((D7*G7)/(1-H7))), "") | H26: =IFERROR(IF(OR(D26="", E26=""), "", E26-D26), "")
A27: =IFERROR(IF(A8="","",A8),"") | B27: =IFERROR(IF(B8="","",B8),"") | C27: =IFERROR(IF(C8="","",C8),"") | D27: =IFERROR(IF(OR(D8="", F8="", H8="", H8>=1), "", (D8*F8)/(1-H8)), "") | E27: =IFERROR(IF(OR(D8="", G8="", I8="", I8>=1), "", (D8*G8)/(1-I8)), "") | F27: =IFERROR(IF(OR(D8="", F8="", G8="", H8="", H8>=1, D27=""), "", ((D8*G8)/(1-H8))-D27), "") | G27: =IFERROR(IF(OR(D8="", G8="", H8="", I8="", H8>=1, I8>=1, E27=""), "", E27-((D8*G8)/(1-H8))), "") | H27: =IFERROR(IF(OR(D27="", E27=""), "", E27-D27), "")
A28: =IFERROR(IF(A9="","",A9),"") | B28: =IFERROR(IF(B9="","",B9),"") | C28: =IFERROR(IF(C9="","",C9),"") | D28: =IFERROR(IF(OR(D9="", F9="", H9="", H9>=1), "", (D9*F9)/(1-H9)), "") | E28: =IFERROR(IF(OR(D9="", G9="", I9="", I9>=1), "", (D9*G9)/(1-I9)), "") | F28: =IFERROR(IF(OR(D9="", F9="", G9="", H9="", H9>=1, D28=""), "", ((D9*G9)/(1-H9))-D28), "") | G28: =IFERROR(IF(OR(D9="", G9="", H9="", I9="", H9>=1, I9>=1, E28=""), "", E28-((D9*G9)/(1-H9))), "") | H28: =IFERROR(IF(OR(D28="", E28=""), "", E28-D28), "")
A29: =IFERROR(IF(A10="","",A10),"") | B29: =IFERROR(IF(B10="","",B10),"") | C29: =IFERROR(IF(C10="","",C10),"") | D29: =IFERROR(IF(OR(D10="", F10="", H10="", H10>=1), "", (D10*F10)/(1-H10)), "") | E29: =IFERROR(IF(OR(D10="", G10="", I10="", I10>=1), "", (D10*G10)/(1-I10)), "") | F29: =IFERROR(IF(OR(D10="", F10="", G10="", H10="", H10>=1, D29=""), "", ((D10*G10)/(1-H10))-D29), "") | G29: =IFERROR(IF(OR(D10="", G10="", H10="", I10="", H10>=1, I10>=1, E29=""), "", E29-((D10*G10)/(1-H10))), "") | H29: =IFERROR(IF(OR(D29="", E29=""), "", E29-D29), "")
A30: =IFERROR(IF(A11="","",A11),"") | B30: =IFERROR(IF(B11="","",B11),"") | C30: =IFERROR(IF(C11="","",C11),"") | D30: =IFERROR(IF(OR(D11="", F11="", H11="", H11>=1), "", (D11*F11)/(1-H11)), "") | E30: =IFERROR(IF(OR(D11="", G11="", I11="", I11>=1), "", (D11*G11)/(1-I11)), "") | F30: =IFERROR(IF(OR(D11="", F11="", G11="", H11="", H11>=1, D30=""), "", ((D11*G11)/(1-H11))-D30), "") | G30: =IFERROR(IF(OR(D11="", G11="", H11="", I11="", H11>=1, I11>=1, E30=""), "", E30-((D11*G11)/(1-H11))), "") | H30: =IFERROR(IF(OR(D30="", E30=""), "", E30-D30), "")
A31: =IFERROR(IF(A12="","",A12),"") | B31: =IFERROR(IF(B12="","",B12),"") | C31: =IFERROR(IF(C12="","",C12),"") | D31: =IFERROR(IF(OR(D12="", F12="", H12="", H12>=1), "", (D12*F12)/(1-H12)), "") | E31: =IFERROR(IF(OR(D12="", G12="", I12="", I12>=1), "", (D12*G12)/(1-I12)), "") | F31: =IFERROR(IF(OR(D12="", F12="", G12="", H12="", H12>=1, D31=""), "", ((D12*G12)/(1-H12))-D31), "") | G31: =IFERROR(IF(OR(D12="", G12="", H12="", I12="", H12>=1, I12>=1, E31=""), "", E31-((D12*G12)/(1-H12))), "") | H31: =IFERROR(IF(OR(D31="", E31=""), "", E31-D31), "")
A32: =IFERROR(IF(A13="","",A13),"") | B32: =IFERROR(IF(B13="","",B13),"") | C32: =IFERROR(IF(C13="","",C13),"") | D32: =IFERROR(IF(OR(D13="", F13="", H13="", H13>=1), "", (D13*F13)/(1-H13)), "") | E32: =IFERROR(IF(OR(D13="", G13="", I13="", I13>=1), "", (D13*G13)/(1-I13)), "") | F32: =IFERROR(IF(OR(D13="", F13="", G13="", H13="", H13>=1, D32=""), "", ((D13*G13)/(1-H13))-D32), "") | G32: =IFERROR(IF(OR(D13="", G13="", H13="", I13="", H13>=1, I13>=1, E32=""), "", E32-((D13*G13)/(1-H13))), "") | H32: =IFERROR(IF(OR(D32="", E32=""), "", E32-D32), "")
A33: =IFERROR(IF(A14="","",A14),"") | B33: =IFERROR(IF(B14="","",B14),"") | C33: =IFERROR(IF(C14="","",C14),"") | D33: =IFERROR(IF(OR(D14="", F14="", H14="", H14>=1), "", (D14*F14)/(1-H14)), "") | E33: =IFERROR(IF(OR(D14="", G14="", I14="", I14>=1), "", (D14*G14)/(1-I14)), "") | F33: =IFERROR(IF(OR(D14="", F14="", G14="", H14="", H14>=1, D33=""), "", ((D14*G14)/(1-H14))-D33), "") | G33: =IFERROR(IF(OR(D14="", G14="", H14="", I14="", H14>=1, I14>=1, E33=""), "", E33-((D14*G14)/(1-H14))), "") | H33: =IFERROR(IF(OR(D33="", E33=""), "", E33-D33), "")
A34: =IFERROR(IF(A15="","",A15),"") | B34: =IFERROR(IF(B15="","",B15),"") | C34: =IFERROR(IF(C15="","",C15),"") | D34: =IFERROR(IF(OR(D15="", F15="", H15="", H15>=1), "", (D15*F15)/(1-H15)), "") | E34: =IFERROR(IF(OR(D15="", G15="", I15="", I15>=1), "", (D15*G15)/(1-I15)), "") | F34: =IFERROR(IF(OR(D15="", F15="", G15="", H15="", H15>=1, D34=""), "", ((D15*G15)/(1-H15))-D34), "") | G34: =IFERROR(IF(OR(D15="", G15="", H15="", I15="", H15>=1, I15>=1, E34=""), "", E34-((D15*G15)/(1-H15))), "") | H34: =IFERROR(IF(OR(D34="", E34=""), "", E34-D34), "")
A35: =IFERROR(IF(A16="","",A16),"") | B35: =IFERROR(IF(B16="","",B16),"") | C35: =IFERROR(IF(C16="","",C16),"") | D35: =IFERROR(IF(OR(D16="", F16="", H16="", H16>=1), "", (D16*F16)/(1-H16)), "") | E35: =IFERROR(IF(OR(D16="", G16="", I16="", I16>=1), "", (D16*G16)/(1-I16)), "") | F35: =IFERROR(IF(OR(D16="", F16="", G16="", H16="", H16>=1, D35=""), "", ((D16*G16)/(1-H16))-D35), "") | G35: =IFERROR(IF(OR(D16="", G16="", H16="", I16="", H16>=1, I16>=1, E35=""), "", E35-((D16*G16)/(1-H16))), "") | H35: =IFERROR(IF(OR(D35="", E35=""), "", E35-D35), "")
... A39: =IFERROR(IF(A20="","",A20),"") | B39: =IFERROR(IF(B20="","",B20),"") | C39: =IFERROR(IF(C20="","",C20),"") | D39: =IFERROR(IF(OR(D20="", F20="", H20="", H20>=1), "", (D20*F20)/(1-H20)), "") | E39: =IFERROR(IF(OR(D20="", G20="", I20="", I20>=1), "", (D20*G20)/(1-I20)), "") | F39: =IFERROR(IF(OR(D20="", F20="", G20="", H20="", H20>=1, D39=""), "", ((D20*G20)/(1-H20))-D39), "") | G39: =IFERROR(IF(OR(D20="", G20="", H20="", I20="", H20>=1, I20>=1, E39=""), "", E39-((D20*G20)/(1-H20))), "") | H39: =IFERROR(IF(OR(D39="", E39=""), "", E39-D39), "")
A40: Total | D40: =IFERROR(IF(SUM(D24:D39)=0, "", SUM(D24:D39)), "") | E40: =IFERROR(IF(SUM(E24:E39)=0, "", SUM(E24:E39)), "") | F40: =IFERROR(IF(SUM(F24:F39)=0, "", SUM(F24:F39)), "") | G40: =IFERROR(IF(SUM(G24:G39)=0, "", SUM(G24:G39)), "") | H40: =IFERROR(IF(SUM(H24:H39)=0, "", SUM(H24:H39)), "")

Sheet 3_ROUTING_BREAKDOWN
A1: CONVERSION PROCESS COST BREAKDOWN (ROUTING)
A3: ROUTING PROCESS INPUT
A4: Sequence | B4: Section | C4: Process Name | D4: Department | E4: MHr | F4: Base Cap (Unit/hr) | G4: Active Cap (Unit/hr) | H4: Base Yield (%) | I4: Active Yield (%) | J4: Source Reference
A45: CONVERSION COST CALCULATION & VARIANCE
A46: Sequence | B46: Section | C46: Process Name | D46: Department | E46: Base Runtime (MHr) | F46: Active Runtime (MHr) | G46: Δ Runtime (MHr) | H46: Base Labor (THB) | I46: Active Labor (THB) | J46: Δ Labor (THB) | K46: Base Burden (THB) | L46: Active Burden (THB) | M46: Δ Burden (THB) | N46: Base Process Cost (THB) | O46: Active Process Cost (THB) | P46: Total Process Δ (THB)
A47: =IFERROR(IF(A5="","",A5),"") | B47: =IFERROR(IF(B5="","",B5),"") | C47: =IFERROR(IF(C5="","",C5),"") | D47: =IFERROR(IF(D5="","",D5),"") | E47: =IFERROR(IF(OR(C5="", F5="", H5="", F5=0, H5=0), "", E5/(F5*H5)), "") | F47: =IFERROR(IF(OR(C5="", G5="", I5="", G5=0, I5=0), "", E5/(G5*I5)), "") | G47: =IFERROR(IF(OR(C5="", E47="", F47=""), "", F47-E47), "") | H47: =IFERROR(IF(OR(C5="", E47=""), "", E47*IFERROR(VLOOKUP(D5,'1_MASTER_RATES'!A$9:E$12,2,FALSE),0)), "") | I47: =IFERROR(IF(OR(C5="", F47=""), "", F47*IFERROR(VLOOKUP(D5,'1_MASTER_RATES'!A$9:E$12,2,FALSE),0)), "") | J47: =IFERROR(IF(OR(C5="", H47="", I47=""), "", I47-H47), "") | K47: =IFERROR(IF(OR(C5="", E47=""), "", E47*IFERROR(VLOOKUP(D5,'1_MASTER_RATES'!A$9:E$12,3,FALSE),0)), "") | L47: =IFERROR(IF(OR(C5="", F47=""), "", F47*IFERROR(VLOOKUP(D5,'1_MASTER_RATES'!A$9:E$12,3,FALSE),0)), "") | M47: =IFERROR(IF(OR(C5="", K47="", L47=""), "", L47-K47), "") | N47: =IFERROR(IF(C5="","", H47+K47), "") | O47: =IFERROR(IF(C5="","", I47+L47), "") | P47: =IFERROR(IF(C5="","", O47-N47), "")
A48: =IFERROR(IF(A6="","",A6),"") | B48: =IFERROR(IF(B6="","",B6),"") | C48: =IFERROR(IF(C6="","",C6),"") | D48: =IFERROR(IF(D6="","",D6),"") | E48: =IFERROR(IF(OR(C6="", F6="", H6="", F6=0, H6=0), "", E6/(F6*H6)), "") | F48: =IFERROR(IF(OR(C6="", G6="", I6="", G6=0, I6=0), "", E6/(G6*I6)), "") | G48: =IFERROR(IF(OR(C6="", E48="", F48=""), "", F48-E48), "") | H48: =IFERROR(IF(OR(C6="", E48=""), "", E48*IFERROR(VLOOKUP(D6,'1_MASTER_RATES'!A$9:E$12,2,FALSE),0)), "") | I48: =IFERROR(IF(OR(C6="", F48=""), "", F48*IFERROR(VLOOKUP(D6,'1_MASTER_RATES'!A$9:E$12,2,FALSE),0)), "") | J48: =IFERROR(IF(OR(C6="", H48="", I48=""), "", I48-H48), "") | K48: =IFERROR(IF(OR(C6="", E48=""), "", E48*IFERROR(VLOOKUP(D6,'1_MASTER_RATES'!A$9:E$12,3,FALSE),0)), "") | L48: =IFERROR(IF(OR(C6="", F48=""), "", F48*IFERROR(VLOOKUP(D6,'1_MASTER_RATES'!A$9:E$12,3,FALSE),0)), "") | M48: =IFERROR(IF(OR(C6="", K48="", L48=""), "", L48-K48), "") | N48: =IFERROR(IF(C6="","", H48+K48), "") | O48: =IFERROR(IF(C6="","", I48+L48), "") | P48: =IFERROR(IF(C6="","", O48-N48), "")
A49: =IFERROR(IF(A7="","",A7),"") | B49: =IFERROR(IF(B7="","",B7),"") | C49: =IFERROR(IF(C7="","",C7),"") | D49: =IFERROR(IF(D7="","",D7),"") | E49: =IFERROR(IF(OR(C7="", F7="", H7="", F7=0, H7=0), "", E7/(F7*H7)), "") | F49: =IFERROR(IF(OR(C7="", G7="", I7="", G7=0, I7=0), "", E7/(G7*I7)), "") | G49: =IFERROR(IF(OR(C7="", E49="", F49=""), "", F49-E49), "") | H49: =IFERROR(IF(OR(C7="", E49=""), "", E49*IFERROR(VLOOKUP(D7,'1_MASTER_RATES'!A$9:E$12,2,FALSE),0)), "") | I49: =IFERROR(IF(OR(C7="", F49=""), "", F49*IFERROR(VLOOKUP(D7,'1_MASTER_RATES'!A$9:E$12,2,FALSE),0)), "") | J49: =IFERROR(IF(OR(C7="", H49="", I49=""), "", I49-H49), "") | K49: =IFERROR(IF(OR(C7="", E49=""), "", E49*IFERROR(VLOOKUP(D7,'1_MASTER_RATES'!A$9:E$12,3,FALSE),0)), "") | L49: =IFERROR(IF(OR(C7="", F49=""), "", F49*IFERROR(VLOOKUP(D7,'1_MASTER_RATES'!A$9:E$12,3,FALSE),0)), "") | M49: =IFERROR(IF(OR(C7="", K49="", L49=""), "", L49-K49), "") | N49: =IFERROR(IF(C7="","", H49+K49), "") | O49: =IFERROR(IF(C7="","", I49+L49), "") | P49: =IFERROR(IF(C7="","", O49-N49), "")
A50: =IFERROR(IF(A8="","",A8),"") | B50: =IFERROR(IF(B8="","",B8),"") | C50: =IFERROR(IF(C8="","",C8),"") | D50: =IFERROR(IF(D8="","",D8),"") | E50: =IFERROR(IF(OR(C8="", F8="", H8="", F8=0, H8=0), "", E8/(F8*H8)), "") | F50: =IFERROR(IF(OR(C8="", G8="", I8="", G8=0, I8=0), "", E8/(G8*I8)), "") | G50: =IFERROR(IF(OR(C8="", E50="", F50=""), "", F50-E50), "") | H50: =IFERROR(IF(OR(C8="", E50=""), "", E50*IFERROR(VLOOKUP(D8,'1_MASTER_RATES'!A$9:E$12,2,FALSE),0)), "") | I50: =IFERROR(IF(OR(C8="", F50=""), "", F50*IFERROR(VLOOKUP(D8,'1_MASTER_RATES'!A$9:E$12,2,FALSE),0)), "") | J50: =IFERROR(IF(OR(C8="", H50="", I50=""), "", I50-H50), "") | K50: =IFERROR(IF(OR(C8="", E50=""), "", E50*IFERROR(VLOOKUP(D8,'1_MASTER_RATES'!A$9:E$12,3,FALSE),0)), "") | L50: =IFERROR(IF(OR(C8="", F50=""), "", F50*IFERROR(VLOOKUP(D8,'1_MASTER_RATES'!A$9:E$12,3,FALSE),0)), "") | M50: =IFERROR(IF(OR(C8="", K50="", L50=""), "", L50-K50), "") | N50: =IFERROR(IF(C8="","", H50+K50), "") | O50: =IFERROR(IF(C8="","", I50+L50), "") | P50: =IFERROR(IF(C8="","", O50-N50), "")
A51: =IFERROR(IF(A9="","",A9),"") | B51: =IFERROR(IF(B9="","",B9),"") | C51: =IFERROR(IF(C9="","",C9),"") | D51: =IFERROR(IF(D9="","",D9),"") | E51: =IFERROR(IF(OR(C9="", F9="", H9="", F9=0, H9=0), "", E9/(F9*H9)), "") | F51: =IFERROR(IF(OR(C9="", G9="", I9="", G9=0, I9=0), "", E9/(G9*I9)), "") | G51: =IFERROR(IF(OR(C9="", E51="", F51=""), "", F51-E51), "") | H51: =IFERROR(IF(OR(C9="", E51=""), "", E51*IFERROR(VLOOKUP(D9,'1_MASTER_RATES'!A$9:E$12,2,FALSE),0)), "") | I51: =IFERROR(IF(OR(C9="", F51=""), "", F51*IFERROR(VLOOKUP(D9,'1_MASTER_RATES'!A$9:E$12,2,FALSE),0)), "") | J51: =IFERROR(IF(OR(C9="", H51="", I51=""), "", I51-H51), "") | K51: =IFERROR(IF(OR(C9="", E51=""), "", E51*IFERROR(VLOOKUP(D9,'1_MASTER_RATES'!A$9:E$12,3,FALSE),0)), "") | L51: =IFERROR(IF(OR(C9="", F51=""), "", F51*IFERROR(VLOOKUP(D9,'1_MASTER_RATES'!A$9:E$12,3,FALSE),0)), "") | M51: =IFERROR(IF(OR(C9="", K51="", L51=""), "", L51-K51), "") | N51: =IFERROR(IF(C9="","", H51+K51), "") | O51: =IFERROR(IF(C9="","", I51+L51), "") | P51: =IFERROR(IF(C9="","", O51-N51), "")
A52: =IFERROR(IF(A10="","",A10),"") | B52: =IFERROR(IF(B10="","",B10),"") | C52: =IFERROR(IF(C10="","",C10),"") | D52: =IFERROR(IF(D10="","",D10),"") | E52: =IFERROR(IF(OR(C10="", F10="", H10="", F10=0, H10=0), "", E10/(F10*H10)), "") | F52: =IFERROR(IF(OR(C10="", G10="", I10="", G10=0, I10=0), "", E10/(G10*I10)), "") | G52: =IFERROR(IF(OR(C10="", E52="", F52=""), "", F52-E52), "") | H52: =IFERROR(IF(OR(C10="", E52=""), "", E52*IFERROR(VLOOKUP(D10,'1_MASTER_RATES'!A$9:E$12,2,FALSE),0)), "") | I52: =IFERROR(IF(OR(C10="", F52=""), "", F52*IFERROR(VLOOKUP(D10,'1_MASTER_RATES'!A$9:E$12,2,FALSE),0)), "") | J52: =IFERROR(IF(OR(C10="", H52="", I52=""), "", I52-H52), "") | K52: =IFERROR(IF(OR(C10="", E52=""), "", E52*IFERROR(VLOOKUP(D10,'1_MASTER_RATES'!A$9:E$12,3,FALSE),0)), "") | L52: =IFERROR(IF(OR(C10="", F52=""), "", F52*IFERROR(VLOOKUP(D10,'1_MASTER_RATES'!A$9:E$12,3,FALSE),0)), "") | M52: =IFERROR(IF(OR(C10="", K52="", L52=""), "", L52-K52), "") | N52: =IFERROR(IF(C10="","", H52+K52), "") | O52: =IFERROR(IF(C10="","", I52+L52), "") | P52: =IFERROR(IF(C10="","", O52-N52), "")
A53: =IFERROR(IF(A11="","",A11),"") | B53: =IFERROR(IF(B11="","",B11),"") | C53: =IFERROR(IF(C11="","",C11),"") | D53: =IFERROR(IF(D11="","",D11),"") | E53: =IFERROR(IF(OR(C11="", F11="", H11="", F11=0, H11=0), "", E11/(F11*H11)), "") | F53: =IFERROR(IF(OR(C11="", G11="", I11="", G11=0, I11=0), "", E11/(G11*I11)), "") | G53: =IFERROR(IF(OR(C11="", E53="", F53=""), "", F53-E53), "") | H53: =IFERROR(IF(OR(C11="", E53=""), "", E53*IFERROR(VLOOKUP(D11,'1_MASTER_RATES'!A$9:E$12,2,FALSE),0)), "") | I53: =IFERROR(IF(OR(C11="", F53=""), "", F53*IFERROR(VLOOKUP(D11,'1_MASTER_RATES'!A$9:E$12,2,FALSE),0)), "") | J53: =IFERROR(IF(OR(C11="", H53="", I53=""), "", I53-H53), "") | K53: =IFERROR(IF(OR(C11="", E53=""), "", E53*IFERROR(VLOOKUP(D11,'1_MASTER_RATES'!A$9:E$12,3,FALSE),0)), "") | L53: =IFERROR(IF(OR(C11="", F53=""), "", F53*IFERROR(VLOOKUP(D11,'1_MASTER_RATES'!A$9:E$12,3,FALSE),0)), "") | M53: =IFERROR(IF(OR(C11="", K53="", L53=""), "", L53-K53), "") | N53: =IFERROR(IF(C11="","", H53+K53), "") | O53: =IFERROR(IF(C11="","", I53+L53), "") | P53: =IFERROR(IF(C11="","", O53-N53), "")
A54: =IFERROR(IF(A12="","",A12),"") | B54: =IFERROR(IF(B12="","",B12),"") | C54: =IFERROR(IF(C12="","",C12),"") | D54: =IFERROR(IF(D12="","",D12),"") | E54: =IFERROR(IF(OR(C12="", F12="", H12="", F12=0, H12=0), "", E12/(F12*H12)), "") | F54: =IFERROR(IF(OR(C12="", G12="", I12="", G12=0, I12=0), "", E12/(G12*I12)), "") | G54: =IFERROR(IF(OR(C12="", E54="", F54=""), "", F54-E54), "") | H54: =IFERROR(IF(OR(C12="", E54=""), "", E54*IFERROR(VLOOKUP(D12,'1_MASTER_RATES'!A$9:E$12,2,FALSE),0)), "") | I54: =IFERROR(IF(OR(C12="", F54=""), "", F54*IFERROR(VLOOKUP(D12,'1_MASTER_RATES'!A$9:E$12,2,FALSE),0)), "") | J54: =IFERROR(IF(OR(C12="", H54="", I54=""), "", I54-H54), "") | K54: =IFERROR(IF(OR(C12="", E54=""), "", E54*IFERROR(VLOOKUP(D12,'1_MASTER_RATES'!A$9:E$12,3,FALSE),0)), "") | L54: =IFERROR(IF(OR(C12="", F54=""), "", F54*IFERROR(VLOOKUP(D12,'1_MASTER_RATES'!A$9:E$12,3,FALSE),0)), "") | M54: =IFERROR(IF(OR(C12="", K54="", L54=""), "", L54-K54), "") | N54: =IFERROR(IF(C12="","", H54+K54), "") | O54: =IFERROR(IF(C12="","", I54+L54), "") | P54: =IFERROR(IF(C12="","", O54-N54), "")
A55: =IFERROR(IF(A13="","",A13),"") | B55: =IFERROR(IF(B13="","",B13),"") | C55: =IFERROR(IF(C13="","",C13),"") | D55: =IFERROR(IF(D13="","",D13),"") | E55: =IFERROR(IF(OR(C13="", F13="", H13="", F13=0, H13=0), "", E13/(F13*H13)), "") | F55: =IFERROR(IF(OR(C13="", G13="", I13="", G13=0, I13=0), "", E13/(G13*I13)), "") | G55: =IFERROR(IF(OR(C13="", E55="", F55=""), "", F55-E55), "") | H55: =IFERROR(IF(OR(C13="", E55=""), "", E55*IFERROR(VLOOKUP(D13,'1_MASTER_RATES'!A$9:E$12,2,FALSE),0)), "") | I55: =IFERROR(IF(OR(C13="", F55=""), "", F55*IFERROR(VLOOKUP(D13,'1_MASTER_RATES'!A$9:E$12,2,FALSE),0)), "") | J55: =IFERROR(IF(OR(C13="", H55="", I55=""), "", I55-H55), "") | K55: =IFERROR(IF(OR(C13="", E55=""), "", E55*IFERROR(VLOOKUP(D13,'1_MASTER_RATES'!A$9:E$12,3,FALSE),0)), "") | L55: =IFERROR(IF(OR(C13="", F55=""), "", F55*IFERROR(VLOOKUP(D13,'1_MASTER_RATES'!A$9:E$12,3,FALSE),0)), "") | M55: =IFERROR(IF(OR(C13="", K55="", L55=""), "", L55-K55), "") | N55: =IFERROR(IF(C13="","", H55+K55), "") | O55: =IFERROR(IF(C13="","", I55+L55), "") | P55: =IFERROR(IF(C13="","", O55-N55), "")
A56: =IFERROR(IF(A14="","",A14),"") | B56: =IFERROR(IF(B14="","",B14),"") | C56: =IFERROR(IF(C14="","",C14),"") | D56: =IFERROR(IF(D14="","",D14),"") | E56: =IFERROR(IF(OR(C14="", F14="", H14="", F14=0, H14=0), "", E14/(F14*H14)), "") | F56: =IFERROR(IF(OR(C14="", G14="", I14="", G14=0, I14=0), "", E14/(G14*I14)), "") | G56: =IFERROR(IF(OR(C14="", E56="", F56=""), "", F56-E56), "") | H56: =IFERROR(IF(OR(C14="", E56=""), "", E56*IFERROR(VLOOKUP(D14,'1_MASTER_RATES'!A$9:E$12,2,FALSE),0)), "") | I56: =IFERROR(IF(OR(C14="", F56=""), "", F56*IFERROR(VLOOKUP(D14,'1_MASTER_RATES'!A$9:E$12,2,FALSE),0)), "") | J56: =IFERROR(IF(OR(C14="", H56="", I56=""), "", I56-H56), "") | K56: =IFERROR(IF(OR(C14="", E56=""), "", E56*IFERROR(VLOOKUP(D14,'1_MASTER_RATES'!A$9:E$12,3,FALSE),0)), "") | L56: =IFERROR(IF(OR(C14="", F56=""), "", F56*IFERROR(VLOOKUP(D14,'1_MASTER_RATES'!A$9:E$12,3,FALSE),0)), "") | M56: =IFERROR(IF(OR(C14="", K56="", L56=""), "", L56-K56), "") | N56: =IFERROR(IF(C14="","", H56+K56), "") | O56: =IFERROR(IF(C14="","", I56+L56), "") | P56: =IFERROR(IF(C14="","", O56-N56), "")
A57: =IFERROR(IF(A15="","",A15),"") | B57: =IFERROR(IF(B15="","",B15),"") | C57: =IFERROR(IF(C15="","",C15),"") | D57: =IFERROR(IF(D15="","",D15),"") | E57: =IFERROR(IF(OR(C15="", F15="", H15="", F15=0, H15=0), "", E15/(F15*H15)), "") | F57: =IFERROR(IF(OR(C15="", G15="", I15="", G15=0, I15=0), "", E15/(G15*I15)), "") | G57: =IFERROR(IF(OR(C15="", E57="", F57=""), "", F57-E57), "") | H57: =IFERROR(IF(OR(C15="", E57=""), "", E57*IFERROR(VLOOKUP(D15,'1_MASTER_RATES'!A$9:E$12,2,FALSE),0)), "") | I57: =IFERROR(IF(OR(C15="", F57=""), "", F57*IFERROR(VLOOKUP(D15,'1_MASTER_RATES'!A$9:E$12,2,FALSE),0)), "") | J57: =IFERROR(IF(OR(C15="", H57="", I57=""), "", I57-H57), "") | K57: =IFERROR(IF(OR(C15="", E57=""), "", E57*IFERROR(VLOOKUP(D15,'1_MASTER_RATES'!A$9:E$12,3,FALSE),0)), "") | L57: =IFERROR(IF(OR(C15="", F57=""), "", F57*IFERROR(VLOOKUP(D15,'1_MASTER_RATES'!A$9:E$12,3,FALSE),0)), "") | M57: =IFERROR(IF(OR(C15="", K57="", L57=""), "", L57-K57), "") | N57: =IFERROR(IF(C15="","", H57+K57), "") | O57: =IFERROR(IF(C15="","", I57+L57), "") | P57: =IFERROR(IF(C15="","", O57-N57), "")
A58: =IFERROR(IF(A16="","",A16),"") | B58: =IFERROR(IF(B16="","",B16),"") | C58: =IFERROR(IF(C16="","",C16),"") | D58: =IFERROR(IF(D16="","",D16),"") | E58: =IFERROR(IF(OR(C16="", F16="", H16="", F16=0, H16=0), "", E16/(F16*H16)), "") | F58: =IFERROR(IF(OR(C16="", G16="", I16="", G16=0, I16=0), "", E16/(G16*I16)), "") | G58: =IFERROR(IF(OR(C16="", E58="", F58=""), "", F58-E58), "") | H58: =IFERROR(IF(OR(C16="", E58=""), "", E58*IFERROR(VLOOKUP(D16,'1_MASTER_RATES'!A$9:E$12,2,FALSE),0)), "") | I58: =IFERROR(IF(OR(C16="", F58=""), "", F58*IFERROR(VLOOKUP(D16,'1_MASTER_RATES'!A$9:E$12,2,FALSE),0)), "") | J58: =IFERROR(IF(OR(C16="", H58="", I58=""), "", I58-H58), "") | K58: =IFERROR(IF(OR(C16="", E58=""), "", E58*IFERROR(VLOOKUP(D16,'1_MASTER_RATES'!A$9:E$12,3,FALSE),0)), "") | L58: =IFERROR(IF(OR(C16="", F58=""), "", F58*IFERROR(VLOOKUP(D16,'1_MASTER_RATES'!A$9:E$12,3,FALSE),0)), "") | M58: =IFERROR(IF(OR(C16="", K58="", L58=""), "", L58-K58), "") | N58: =IFERROR(IF(C16="","", H58+K58), "") | O58: =IFERROR(IF(C16="","", I58+L58), "") | P58: =IFERROR(IF(C16="","", O58-N58), "")
... A85: =IFERROR(IF(A43="","",A43),"") | B85: =IFERROR(IF(B43="","",B43),"") | C85: =IFERROR(IF(C43="","",C43),"") | D85: =IFERROR(IF(D43="","",D43),"") | E85: =IFERROR(IF(OR(C43="", F43="", H43="", F43=0, H43=0), "", E43/(F43*H43)), "") | F85: =IFERROR(IF(OR(C43="", G43="", I43="", G43=0, I43=0), "", E43/(G43*I43)), "") | G85: =IFERROR(IF(OR(C43="", E85="", F85=""), "", F85-E85), "") | H85: =IFERROR(IF(OR(C43="", E85=""), "", E85*IFERROR(VLOOKUP(D43,'1_MASTER_RATES'!A$9:E$12,2,FALSE),0)), "") | I85: =IFERROR(IF(OR(C43="", F85=""), "", F85*IFERROR(VLOOKUP(D43,'1_MASTER_RATES'!A$9:E$12,2,FALSE),0)), "") | J85: =IFERROR(IF(OR(C43="", H85="", I85=""), "", I85-H85), "") | K85: =IFERROR(IF(OR(C43="", E85=""), "", E85*IFERROR(VLOOKUP(D43,'1_MASTER_RATES'!A$9:E$12,3,FALSE),0)), "") | L85: =IFERROR(IF(OR(C43="", F85=""), "", F85*IFERROR(VLOOKUP(D43,'1_MASTER_RATES'!A$9:E$12,3,FALSE),0)), "") | M85: =IFERROR(IF(OR(C43="", K85="", L85=""), "", L85-K85), "") | N85: =IFERROR(IF(C43="","", H85+K85), "") | O85: =IFERROR(IF(C43="","", I85+L85), "") | P85: =IFERROR(IF(C43="","", O85-N85), "")
A86: Total | H86: =IFERROR(IF(SUM(H47:H85)=0, "", SUM(H47:H85)), "") | I86: =IFERROR(IF(SUM(I47:I85)=0, "", SUM(I47:I85)), "") | J86: =IFERROR(IF(SUM(J47:J85)=0, "", SUM(J47:J85)), "") | K86: =IFERROR(IF(SUM(K47:K85)=0, "", SUM(K47:K85)), "") | L86: =IFERROR(IF(SUM(L47:L85)=0, "", SUM(L47:L85)), "") | M86: =IFERROR(IF(SUM(M47:M85)=0, "", SUM(M47:M85)), "") | N86: =IFERROR(IF(SUM(N47:N85)=0, "", SUM(N47:N85)), "") | O86: =IFERROR(IF(SUM(O47:O85)=0, "", SUM(O47:O85)), "") | P86: =IFERROR(IF(SUM(P47:P85)=0, "", SUM(P47:P85)), "")

Sheet _CALC_ENGINE
A1: DYNAMIC COST DRIVER RANKING & EVALUATION ENGINE
A3: ID | B3: Level 2 Category | C3: Level 3 Driver Name | D3: Level 4 RCA Parameter | E3: Base Parameter | F3: Active Parameter | G3: Cost Gap (THB / Unit) | H3: Tie-Breaker Score
A4: 1 | B4: =IFERROR(IF('2_BOM_BREAKDOWN'!C5="","","Direct Material"),"") | C4: =IFERROR(IF('2_BOM_BREAKDOWN'!C5="","",'2_BOM_BREAKDOWN'!C5),"") | D4: =IFERROR(IF(OR('2_BOM_BREAKDOWN'!C5="",""),"",IF('2_BOM_BREAKDOWN'!G5>'2_BOM_BREAKDOWN'!F5,"Unit Price Inflation ("&TEXT('2_BOM_BREAKDOWN'!F5,"#,##0.00")&" ➔ "&TEXT('2_BOM_BREAKDOWN'!G5,"#,##0.00")&" THB)",IF('2_BOM_BREAKDOWN'!G5<'2_BOM_BREAKDOWN'!F5,"Unit Price Reduction ("&TEXT('2_BOM_BREAKDOWN'!F5,"#,##0.00")&" ➔ "&TEXT('2_BOM_BREAKDOWN'!G5,"#,##0.00")&" THB)",IF('2_BOM_BREAKDOWN'!I5>'2_BOM_BREAKDOWN'!H5,"Loss % Increase ("&TEXT('2_BOM_BREAKDOWN'!H5,"0.0%")&" ➔ "&TEXT('2_BOM_BREAKDOWN'!I5,"0.0%")&")",IF('2_BOM_BREAKDOWN'!I5<'2_BOM_BREAKDOWN'!H5,"Loss % Reduction ("&TEXT('2_BOM_BREAKDOWN'!H5,"0.0%")&" ➔ "&TEXT('2_BOM_BREAKDOWN'!I5,"0.0%")&")",""))))),"") | E4: =IFERROR(IF(OR('2_BOM_BREAKDOWN'!C5="",""),"",IF('2_BOM_BREAKDOWN'!G5<>'2_BOM_BREAKDOWN'!F5,'2_BOM_BREAKDOWN'!F5,IF('2_BOM_BREAKDOWN'!I5<>'2_BOM_BREAKDOWN'!H5,'2_BOM_BREAKDOWN'!H5,""))),"") | F4: =IFERROR(IF(OR('2_BOM_BREAKDOWN'!C5="",""),"",IF('2_BOM_BREAKDOWN'!G5<>'2_BOM_BREAKDOWN'!F5,'2_BOM_BREAKDOWN'!G5,IF('2_BOM_BREAKDOWN'!I5<>'2_BOM_BREAKDOWN'!H5,'2_BOM_BREAKDOWN'!I5,""))),"") | G4: =IFERROR(IF(OR('2_BOM_BREAKDOWN'!C5="",'2_BOM_BREAKDOWN'!H24=""),"",'2_BOM_BREAKDOWN'!H24),"") | H4: =IFERROR(IF(OR(G4="",G4<=0), "", G4+(55-A4)*0.00000001), "")
A5: 2 | B5: =IFERROR(IF('2_BOM_BREAKDOWN'!C6="","","Direct Material"),"") | C5: =IFERROR(IF('2_BOM_BREAKDOWN'!C6="","",'2_BOM_BREAKDOWN'!C6),"") | D5: =IFERROR(IF(OR('2_BOM_BREAKDOWN'!C6="",""),"",IF('2_BOM_BREAKDOWN'!G6>'2_BOM_BREAKDOWN'!F6,"Unit Price Inflation ("&TEXT('2_BOM_BREAKDOWN'!F6,"#,##0.00")&" ➔ "&TEXT('2_BOM_BREAKDOWN'!G6,"#,##0.00")&" THB)",IF('2_BOM_BREAKDOWN'!G6<'2_BOM_BREAKDOWN'!F6,"Unit Price Reduction ("&TEXT('2_BOM_BREAKDOWN'!F6,"#,##0.00")&" ➔ "&TEXT('2_BOM_BREAKDOWN'!G6,"#,##0.00")&" THB)",IF('2_BOM_BREAKDOWN'!I6>'2_BOM_BREAKDOWN'!H6,"Loss % Increase ("&TEXT('2_BOM_BREAKDOWN'!H6,"0.0%")&" ➔ "&TEXT('2_BOM_BREAKDOWN'!I6,"0.0%")&")",IF('2_BOM_BREAKDOWN'!I6<'2_BOM_BREAKDOWN'!H6,"Loss % Reduction ("&TEXT('2_BOM_BREAKDOWN'!H6,"0.0%")&" ➔ "&TEXT('2_BOM_BREAKDOWN'!I6,"0.0%")&")",""))))),"") | E5: =IFERROR(IF(OR('2_BOM_BREAKDOWN'!C6="",""),"",IF('2_BOM_BREAKDOWN'!G6<>'2_BOM_BREAKDOWN'!F6,'2_BOM_BREAKDOWN'!F6,IF('2_BOM_BREAKDOWN'!I6<>'2_BOM_BREAKDOWN'!H6,'2_BOM_BREAKDOWN'!H6,""))),"") | F5: =IFERROR(IF(OR('2_BOM_BREAKDOWN'!C6="",""),"",IF('2_BOM_BREAKDOWN'!G6<>'2_BOM_BREAKDOWN'!F6,'2_BOM_BREAKDOWN'!G6,IF('2_BOM_BREAKDOWN'!I6<>'2_BOM_BREAKDOWN'!H6,'2_BOM_BREAKDOWN'!I6,""))),"") | G5: =IFERROR(IF(OR('2_BOM_BREAKDOWN'!C6="",'2_BOM_BREAKDOWN'!H25=""),"",'2_BOM_BREAKDOWN'!H25),"") | H5: =IFERROR(IF(OR(G5="",G5<=0), "", G5+(55-A5)*0.00000001), "")
A6: 3 | B6: =IFERROR(IF('2_BOM_BREAKDOWN'!C7="","","Direct Material"),"") | C6: =IFERROR(IF('2_BOM_BREAKDOWN'!C7="","",'2_BOM_BREAKDOWN'!C7),"") | D6: =IFERROR(IF(OR('2_BOM_BREAKDOWN'!C7="",""),"",IF('2_BOM_BREAKDOWN'!G7>'2_BOM_BREAKDOWN'!F7,"Unit Price Inflation ("&TEXT('2_BOM_BREAKDOWN'!F7,"#,##0.00")&" ➔ "&TEXT('2_BOM_BREAKDOWN'!G7,"#,##0.00")&" THB)",IF('2_BOM_BREAKDOWN'!G7<'2_BOM_BREAKDOWN'!F7,"Unit Price Reduction ("&TEXT('2_BOM_BREAKDOWN'!F7,"#,##0.00")&" ➔ "&TEXT('2_BOM_BREAKDOWN'!G7,"#,##0.00")&" THB)",IF('2_BOM_BREAKDOWN'!I7>'2_BOM_BREAKDOWN'!H7,"Loss % Increase ("&TEXT('2_BOM_BREAKDOWN'!H7,"0.0%")&" ➔ "&TEXT('2_BOM_BREAKDOWN'!I7,"0.0%")&")",IF('2_BOM_BREAKDOWN'!I7<'2_BOM_BREAKDOWN'!H7,"Loss % Reduction ("&TEXT('2_BOM_BREAKDOWN'!H7,"0.0%")&" ➔ "&TEXT('2_BOM_BREAKDOWN'!I7,"0.0%")&")",""))))),"") | E6: =IFERROR(IF(OR('2_BOM_BREAKDOWN'!C7="",""),"",IF('2_BOM_BREAKDOWN'!G7<>'2_BOM_BREAKDOWN'!F7,'2_BOM_BREAKDOWN'!F7,IF('2_BOM_BREAKDOWN'!I7<>'2_BOM_BREAKDOWN'!H7,'2_BOM_BREAKDOWN'!H7,""))),"") | F6: =IFERROR(IF(OR('2_BOM_BREAKDOWN'!C7="",""),"",IF('2_BOM_BREAKDOWN'!G7<>'2_BOM_BREAKDOWN'!F7,'2_BOM_BREAKDOWN'!G7,IF('2_BOM_BREAKDOWN'!I7<>'2_BOM_BREAKDOWN'!H7,'2_BOM_BREAKDOWN'!I7,""))),"") | G6: =IFERROR(IF(OR('2_BOM_BREAKDOWN'!C7="",'2_BOM_BREAKDOWN'!H26=""),"",'2_BOM_BREAKDOWN'!H26),"") | H6: =IFERROR(IF(OR(G6="",G6<=0), "", G6+(55-A6)*0.00000001), "")
A7: 4 | B7: =IFERROR(IF('2_BOM_BREAKDOWN'!C8="","","Direct Material"),"") | C7: =IFERROR(IF('2_BOM_BREAKDOWN'!C8="","",'2_BOM_BREAKDOWN'!C8),"") | D7: =IFERROR(IF(OR('2_BOM_BREAKDOWN'!C8="",""),"",IF('2_BOM_BREAKDOWN'!G8>'2_BOM_BREAKDOWN'!F8,"Unit Price Inflation ("&TEXT('2_BOM_BREAKDOWN'!F8,"#,##0.00")&" ➔ "&TEXT('2_BOM_BREAKDOWN'!G8,"#,##0.00")&" THB)",IF('2_BOM_BREAKDOWN'!G8<'2_BOM_BREAKDOWN'!F8,"Unit Price Reduction ("&TEXT('2_BOM_BREAKDOWN'!F8,"#,##0.00")&" ➔ "&TEXT('2_BOM_BREAKDOWN'!G8,"#,##0.00")&" THB)",IF('2_BOM_BREAKDOWN'!I8>'2_BOM_BREAKDOWN'!H8,"Loss % Increase ("&TEXT('2_BOM_BREAKDOWN'!H8,"0.0%")&" ➔ "&TEXT('2_BOM_BREAKDOWN'!I8,"0.0%")&")",IF('2_BOM_BREAKDOWN'!I8<'2_BOM_BREAKDOWN'!H8,"Loss % Reduction ("&TEXT('2_BOM_BREAKDOWN'!H8,"0.0%")&" ➔ "&TEXT('2_BOM_BREAKDOWN'!I8,"0.0%")&")",""))))),"") | E7: =IFERROR(IF(OR('2_BOM_BREAKDOWN'!C8="",""),"",IF('2_BOM_BREAKDOWN'!G8<>'2_BOM_BREAKDOWN'!F8,'2_BOM_BREAKDOWN'!F8,IF('2_BOM_BREAKDOWN'!I8<>'2_BOM_BREAKDOWN'!H8,'2_BOM_BREAKDOWN'!H8,""))),"") | F7: =IFERROR(IF(OR('2_BOM_BREAKDOWN'!C8="",""),"",IF('2_BOM_BREAKDOWN'!G8<>'2_BOM_BREAKDOWN'!F8,'2_BOM_BREAKDOWN'!G8,IF('2_BOM_BREAKDOWN'!I8<>'2_BOM_BREAKDOWN'!H8,'2_BOM_BREAKDOWN'!I8,""))),"") | G7: =IFERROR(IF(OR('2_BOM_BREAKDOWN'!C8="",'2_BOM_BREAKDOWN'!H27=""),"",'2_BOM_BREAKDOWN'!H27),"") | H7: =IFERROR(IF(OR(G7="",G7<=0), "", G7+(55-A7)*0.00000001), "")
A8: 5 | B8: =IFERROR(IF('2_BOM_BREAKDOWN'!C9="","","Direct Material"),"") | C8: =IFERROR(IF('2_BOM_BREAKDOWN'!C9="","",'2_BOM_BREAKDOWN'!C9),"") | D8: =IFERROR(IF(OR('2_BOM_BREAKDOWN'!C9="",""),"",IF('2_BOM_BREAKDOWN'!G9>'2_BOM_BREAKDOWN'!F9,"Unit Price Inflation ("&TEXT('2_BOM_BREAKDOWN'!F9,"#,##0.00")&" ➔ "&TEXT('2_BOM_BREAKDOWN'!G9,"#,##0.00")&" THB)",IF('2_BOM_BREAKDOWN'!G9<'2_BOM_BREAKDOWN'!F9,"Unit Price Reduction ("&TEXT('2_BOM_BREAKDOWN'!F9,"#,##0.00")&" ➔ "&TEXT('2_BOM_BREAKDOWN'!G9,"#,##0.00")&" THB)",IF('2_BOM_BREAKDOWN'!I9>'2_BOM_BREAKDOWN'!H9,"Loss % Increase ("&TEXT('2_BOM_BREAKDOWN'!H9,"0.0%")&" ➔ "&TEXT('2_BOM_BREAKDOWN'!I9,"0.0%")&")",IF('2_BOM_BREAKDOWN'!I9<'2_BOM_BREAKDOWN'!H9,"Loss % Reduction ("&TEXT('2_BOM_BREAKDOWN'!H9,"0.0%")&" ➔ "&TEXT('2_BOM_BREAKDOWN'!I9,"0.0%")&")",""))))),"") | E8: =IFERROR(IF(OR('2_BOM_BREAKDOWN'!C9="",""),"",IF('2_BOM_BREAKDOWN'!G9<>'2_BOM_BREAKDOWN'!F9,'2_BOM_BREAKDOWN'!F9,IF('2_BOM_BREAKDOWN'!I9<>'2_BOM_BREAKDOWN'!H9,'2_BOM_BREAKDOWN'!H9,""))),"") | F8: =IFERROR(IF(OR('2_BOM_BREAKDOWN'!C9="",""),"",IF('2_BOM_BREAKDOWN'!G9<>'2_BOM_BREAKDOWN'!F9,'2_BOM_BREAKDOWN'!G9,IF('2_BOM_BREAKDOWN'!I9<>'2_BOM_BREAKDOWN'!H9,'2_BOM_BREAKDOWN'!I9,""))),"") | G8: =IFERROR(IF(OR('2_BOM_BREAKDOWN'!C9="",'2_BOM_BREAKDOWN'!H28=""),"",'2_BOM_BREAKDOWN'!H28),"") | H8: =IFERROR(IF(OR(G8="",G8<=0), "", G8+(55-A8)*0.00000001), "")
A9: 6 | B9: =IFERROR(IF('2_BOM_BREAKDOWN'!C10="","","Direct Material"),"") | C9: =IFERROR(IF('2_BOM_BREAKDOWN'!C10="","",'2_BOM_BREAKDOWN'!C10),"") | D9: =IFERROR(IF(OR('2_BOM_BREAKDOWN'!C10="",""),"",IF('2_BOM_BREAKDOWN'!G10>'2_BOM_BREAKDOWN'!F10,"Unit Price Inflation ("&TEXT('2_BOM_BREAKDOWN'!F10,"#,##0.00")&" ➔ "&TEXT('2_BOM_BREAKDOWN'!G10,"#,##0.00")&" THB)",IF('2_BOM_BREAKDOWN'!G10<'2_BOM_BREAKDOWN'!F10,"Unit Price Reduction ("&TEXT('2_BOM_BREAKDOWN'!F10,"#,##0.00")&" ➔ "&TEXT('2_BOM_BREAKDOWN'!G10,"#,##0.00")&" THB)",IF('2_BOM_BREAKDOWN'!I10>'2_BOM_BREAKDOWN'!H10,"Loss % Increase ("&TEXT('2_BOM_BREAKDOWN'!H10,"0.0%")&" ➔ "&TEXT('2_BOM_BREAKDOWN'!I10,"0.0%")&")",IF('2_BOM_BREAKDOWN'!I10<'2_BOM_BREAKDOWN'!H10,"Loss % Reduction ("&TEXT('2_BOM_BREAKDOWN'!H10,"0.0%")&" ➔ "&TEXT('2_BOM_BREAKDOWN'!I10,"0.0%")&")",""))))),"") | E9: =IFERROR(IF(OR('2_BOM_BREAKDOWN'!C10="",""),"",IF('2_BOM_BREAKDOWN'!G10<>'2_BOM_BREAKDOWN'!F10,'2_BOM_BREAKDOWN'!F10,IF('2_BOM_BREAKDOWN'!I10<>'2_BOM_BREAKDOWN'!H10,'2_BOM_BREAKDOWN'!H10,""))),"") | F9: =IFERROR(IF(OR('2_BOM_BREAKDOWN'!C10="",""),"",IF('2_BOM_BREAKDOWN'!G10<>'2_BOM_BREAKDOWN'!F10,'2_BOM_BREAKDOWN'!G10,IF('2_BOM_BREAKDOWN'!I10<>'2_BOM_BREAKDOWN'!H10,'2_BOM_BREAKDOWN'!I10,""))),"") | G9: =IFERROR(IF(OR('2_BOM_BREAKDOWN'!C10="",'2_BOM_BREAKDOWN'!H29=""),"",'2_BOM_BREAKDOWN'!H29),"") | H9: =IFERROR(IF(OR(G9="",G9<=0), "", G9+(55-A9)*0.00000001), "")
A10: 7 | B10: =IFERROR(IF('2_BOM_BREAKDOWN'!C11="","","Direct Material"),"") | C10: =IFERROR(IF('2_BOM_BREAKDOWN'!C11="","",'2_BOM_BREAKDOWN'!C11),"") | D10: =IFERROR(IF(OR('2_BOM_BREAKDOWN'!C11="",""),"",IF('2_BOM_BREAKDOWN'!G11>'2_BOM_BREAKDOWN'!F11,"Unit Price Inflation ("&TEXT('2_BOM_BREAKDOWN'!F11,"#,##0.00")&" ➔ "&TEXT('2_BOM_BREAKDOWN'!G11,"#,##0.00")&" THB)",IF('2_BOM_BREAKDOWN'!G11<'2_BOM_BREAKDOWN'!F11,"Unit Price Reduction ("&TEXT('2_BOM_BREAKDOWN'!F11,"#,##0.00")&" ➔ "&TEXT('2_BOM_BREAKDOWN'!G11,"#,##0.00")&" THB)",IF('2_BOM_BREAKDOWN'!I11>'2_BOM_BREAKDOWN'!H11,"Loss % Increase ("&TEXT('2_BOM_BREAKDOWN'!H11,"0.0%")&" ➔ "&TEXT('2_BOM_BREAKDOWN'!I11,"0.0%")&")",IF('2_BOM_BREAKDOWN'!I11<'2_BOM_BREAKDOWN'!H11,"Loss % Reduction ("&TEXT('2_BOM_BREAKDOWN'!H11,"0.0%")&" ➔ "&TEXT('2_BOM_BREAKDOWN'!I11,"0.0%")&")",""))))),"") | E10: =IFERROR(IF(OR('2_BOM_BREAKDOWN'!C11="",""),"",IF('2_BOM_BREAKDOWN'!G11<>'2_BOM_BREAKDOWN'!F11,'2_BOM_BREAKDOWN'!F11,IF('2_BOM_BREAKDOWN'!I11<>'2_BOM_BREAKDOWN'!H11,'2_BOM_BREAKDOWN'!H11,""))),"") | F10: =IFERROR(IF(OR('2_BOM_BREAKDOWN'!C11="",""),"",IF('2_BOM_BREAKDOWN'!G11<>'2_BOM_BREAKDOWN'!F11,'2_BOM_BREAKDOWN'!G11,IF('2_BOM_BREAKDOWN'!I11<>'2_BOM_BREAKDOWN'!H11,'2_BOM_BREAKDOWN'!I11,""))),"") | G10: =IFERROR(IF(OR('2_BOM_BREAKDOWN'!C11="",'2_BOM_BREAKDOWN'!H30=""),"",'2_BOM_BREAKDOWN'!H30),"") | H10: =IFERROR(IF(OR(G10="",G10<=0), "", G10+(55-A10)*0.00000001), "")
A11: 8 | B11: =IFERROR(IF('2_BOM_BREAKDOWN'!C12="","","Direct Material"),"") | C11: =IFERROR(IF('2_BOM_BREAKDOWN'!C12="","",'2_BOM_BREAKDOWN'!C12),"") | D11: =IFERROR(IF(OR('2_BOM_BREAKDOWN'!C12="",""),"",IF('2_BOM_BREAKDOWN'!G12>'2_BOM_BREAKDOWN'!F12,"Unit Price Inflation ("&TEXT('2_BOM_BREAKDOWN'!F12,"#,##0.00")&" ➔ "&TEXT('2_BOM_BREAKDOWN'!G12,"#,##0.00")&" THB)",IF('2_BOM_BREAKDOWN'!G12<'2_BOM_BREAKDOWN'!F12,"Unit Price Reduction ("&TEXT('2_BOM_BREAKDOWN'!F12,"#,##0.00")&" ➔ "&TEXT('2_BOM_BREAKDOWN'!G12,"#,##0.00")&" THB)",IF('2_BOM_BREAKDOWN'!I12>'2_BOM_BREAKDOWN'!H12,"Loss % Increase ("&TEXT('2_BOM_BREAKDOWN'!H12,"0.0%")&" ➔ "&TEXT('2_BOM_BREAKDOWN'!I12,"0.0%")&")",IF('2_BOM_BREAKDOWN'!I12<'2_BOM_BREAKDOWN'!H12,"Loss % Reduction ("&TEXT('2_BOM_BREAKDOWN'!H12,"0.0%")&" ➔ "&TEXT('2_BOM_BREAKDOWN'!I12,"0.0%")&")",""))))),"") | E11: =IFERROR(IF(OR('2_BOM_BREAKDOWN'!C12="",""),"",IF('2_BOM_BREAKDOWN'!G12<>'2_BOM_BREAKDOWN'!F12,'2_BOM_BREAKDOWN'!F12,IF('2_BOM_BREAKDOWN'!I12<>'2_BOM_BREAKDOWN'!H12,'2_BOM_BREAKDOWN'!H12,""))),"") | F11: =IFERROR(IF(OR('2_BOM_BREAKDOWN'!C12="",""),"",IF('2_BOM_BREAKDOWN'!G12<>'2_BOM_BREAKDOWN'!F12,'2_BOM_BREAKDOWN'!G12,IF('2_BOM_BREAKDOWN'!I12<>'2_BOM_BREAKDOWN'!H12,'2_BOM_BREAKDOWN'!I12,""))),"") | G11: =IFERROR(IF(OR('2_BOM_BREAKDOWN'!C12="",'2_BOM_BREAKDOWN'!H31=""),"",'2_BOM_BREAKDOWN'!H31),"") | H11: =IFERROR(IF(OR(G11="",G11<=0), "", G11+(55-A11)*0.00000001), "")
A12: 9 | B12: =IFERROR(IF('2_BOM_BREAKDOWN'!C13="","","Direct Material"),"") | C12: =IFERROR(IF('2_BOM_BREAKDOWN'!C13="","",'2_BOM_BREAKDOWN'!C13),"") | D12: =IFERROR(IF(OR('2_BOM_BREAKDOWN'!C13="",""),"",IF('2_BOM_BREAKDOWN'!G13>'2_BOM_BREAKDOWN'!F13,"Unit Price Inflation ("&TEXT('2_BOM_BREAKDOWN'!F13,"#,##0.00")&" ➔ "&TEXT('2_BOM_BREAKDOWN'!G13,"#,##0.00")&" THB)",IF('2_BOM_BREAKDOWN'!G13<'2_BOM_BREAKDOWN'!F13,"Unit Price Reduction ("&TEXT('2_BOM_BREAKDOWN'!F13,"#,##0.00")&" ➔ "&TEXT('2_BOM_BREAKDOWN'!G13,"#,##0.00")&" THB)",IF('2_BOM_BREAKDOWN'!I13>'2_BOM_BREAKDOWN'!H13,"Loss % Increase ("&TEXT('2_BOM_BREAKDOWN'!H13,"0.0%")&" ➔ "&TEXT('2_BOM_BREAKDOWN'!I13,"0.0%")&")",IF('2_BOM_BREAKDOWN'!I13<'2_BOM_BREAKDOWN'!H13,"Loss % Reduction ("&TEXT('2_BOM_BREAKDOWN'!H13,"0.0%")&" ➔ "&TEXT('2_BOM_BREAKDOWN'!I13,"0.0%")&")",""))))),"") | E12: =IFERROR(IF(OR('2_BOM_BREAKDOWN'!C13="",""),"",IF('2_BOM_BREAKDOWN'!G13<>'2_BOM_BREAKDOWN'!F13,'2_BOM_BREAKDOWN'!F13,IF('2_BOM_BREAKDOWN'!I13<>'2_BOM_BREAKDOWN'!H13,'2_BOM_BREAKDOWN'!H13,""))),"") | F12: =IFERROR(IF(OR('2_BOM_BREAKDOWN'!C13="",""),"",IF('2_BOM_BREAKDOWN'!G13<>'2_BOM_BREAKDOWN'!F13,'2_BOM_BREAKDOWN'!G13,IF('2_BOM_BREAKDOWN'!I13<>'2_BOM_BREAKDOWN'!H13,'2_BOM_BREAKDOWN'!I13,""))),"") | G12: =IFERROR(IF(OR('2_BOM_BREAKDOWN'!C13="",'2_BOM_BREAKDOWN'!H32=""),"",'2_BOM_BREAKDOWN'!H32),"") | H12: =IFERROR(IF(OR(G12="",G12<=0), "", G12+(55-A12)*0.00000001), "")
A13: 10 | B13: =IFERROR(IF('2_BOM_BREAKDOWN'!C14="","","Direct Material"),"") | C13: =IFERROR(IF('2_BOM_BREAKDOWN'!C14="","",'2_BOM_BREAKDOWN'!C14),"") | D13: =IFERROR(IF(OR('2_BOM_BREAKDOWN'!C14="",""),"",IF('2_BOM_BREAKDOWN'!G14>'2_BOM_BREAKDOWN'!F14,"Unit Price Inflation ("&TEXT('2_BOM_BREAKDOWN'!F14,"#,##0.00")&" ➔ "&TEXT('2_BOM_BREAKDOWN'!G14,"#,##0.00")&" THB)",IF('2_BOM_BREAKDOWN'!G14<'2_BOM_BREAKDOWN'!F14,"Unit Price Reduction ("&TEXT('2_BOM_BREAKDOWN'!F14,"#,##0.00")&" ➔ "&TEXT('2_BOM_BREAKDOWN'!G14,"#,##0.00")&" THB)",IF('2_BOM_BREAKDOWN'!I14>'2_BOM_BREAKDOWN'!H14,"Loss % Increase ("&TEXT('2_BOM_BREAKDOWN'!H14,"0.0%")&" ➔ "&TEXT('2_BOM_BREAKDOWN'!I14,"0.0%")&")",IF('2_BOM_BREAKDOWN'!I14<'2_BOM_BREAKDOWN'!H14,"Loss % Reduction ("&TEXT('2_BOM_BREAKDOWN'!H14,"0.0%")&" ➔ "&TEXT('2_BOM_BREAKDOWN'!I14,"0.0%")&")",""))))),"") | E13: =IFERROR(IF(OR('2_BOM_BREAKDOWN'!C14="",""),"",IF('2_BOM_BREAKDOWN'!G14<>'2_BOM_BREAKDOWN'!F14,'2_BOM_BREAKDOWN'!F14,IF('2_BOM_BREAKDOWN'!I14<>'2_BOM_BREAKDOWN'!H14,'2_BOM_BREAKDOWN'!H14,""))),"") | F13: =IFERROR(IF(OR('2_BOM_BREAKDOWN'!C14="",""),"",IF('2_BOM_BREAKDOWN'!G14<>'2_BOM_BREAKDOWN'!F14,'2_BOM_BREAKDOWN'!G14,IF('2_BOM_BREAKDOWN'!I14<>'2_BOM_BREAKDOWN'!H14,'2_BOM_BREAKDOWN'!I14,""))),"") | G13: =IFERROR(IF(OR('2_BOM_BREAKDOWN'!C14="",'2_BOM_BREAKDOWN'!H33=""),"",'2_BOM_BREAKDOWN'!H33),"") | H13: =IFERROR(IF(OR(G13="",G13<=0), "", G13+(55-A13)*0.00000001), "")
A14: 11 | B14: =IFERROR(IF('2_BOM_BREAKDOWN'!C15="","","Direct Material"),"") | C14: =IFERROR(IF('2_BOM_BREAKDOWN'!C15="","",'2_BOM_BREAKDOWN'!C15),"") | D14: =IFERROR(IF(OR('2_BOM_BREAKDOWN'!C15="",""),"",IF('2_BOM_BREAKDOWN'!G15>'2_BOM_BREAKDOWN'!F15,"Unit Price Inflation ("&TEXT('2_BOM_BREAKDOWN'!F15,"#,##0.00")&" ➔ "&TEXT('2_BOM_BREAKDOWN'!G15,"#,##0.00")&" THB)",IF('2_BOM_BREAKDOWN'!G15<'2_BOM_BREAKDOWN'!F15,"Unit Price Reduction ("&TEXT('2_BOM_BREAKDOWN'!F15,"#,##0.00")&" ➔ "&TEXT('2_BOM_BREAKDOWN'!G15,"#,##0.00")&" THB)",IF('2_BOM_BREAKDOWN'!I15>'2_BOM_BREAKDOWN'!H15,"Loss % Increase ("&TEXT('2_BOM_BREAKDOWN'!H15,"0.0%")&" ➔ "&TEXT('2_BOM_BREAKDOWN'!I15,"0.0%")&")",IF('2_BOM_BREAKDOWN'!I15<'2_BOM_BREAKDOWN'!H15,"Loss % Reduction ("&TEXT('2_BOM_BREAKDOWN'!H15,"0.0%")&" ➔ "&TEXT('2_BOM_BREAKDOWN'!I15,"0.0%")&")",""))))),"") | E14: =IFERROR(IF(OR('2_BOM_BREAKDOWN'!C15="",""),"",IF('2_BOM_BREAKDOWN'!G15<>'2_BOM_BREAKDOWN'!F15,'2_BOM_BREAKDOWN'!F15,IF('2_BOM_BREAKDOWN'!I15<>'2_BOM_BREAKDOWN'!H15,'2_BOM_BREAKDOWN'!H15,""))),"") | F14: =IFERROR(IF(OR('2_BOM_BREAKDOWN'!C15="",""),"",IF('2_BOM_BREAKDOWN'!G15<>'2_BOM_BREAKDOWN'!F15,'2_BOM_BREAKDOWN'!G15,IF('2_BOM_BREAKDOWN'!I15<>'2_BOM_BREAKDOWN'!H15,'2_BOM_BREAKDOWN'!I15,""))),"") | G14: =IFERROR(IF(OR('2_BOM_BREAKDOWN'!C15="",'2_BOM_BREAKDOWN'!H34=""),"",'2_BOM_BREAKDOWN'!H34),"") | H14: =IFERROR(IF(OR(G14="",G14<=0), "", G14+(55-A14)*0.00000001), "")
A15: 12 | B15: =IFERROR(IF('2_BOM_BREAKDOWN'!C16="","","Direct Material"),"") | C15: =IFERROR(IF('2_BOM_BREAKDOWN'!C16="","",'2_BOM_BREAKDOWN'!C16),"") | D15: =IFERROR(IF(OR('2_BOM_BREAKDOWN'!C16="",""),"",IF('2_BOM_BREAKDOWN'!G16>'2_BOM_BREAKDOWN'!F16,"Unit Price Inflation ("&TEXT('2_BOM_BREAKDOWN'!F16,"#,##0.00")&" ➔ "&TEXT('2_BOM_BREAKDOWN'!G16,"#,##0.00")&" THB)",IF('2_BOM_BREAKDOWN'!G16<'2_BOM_BREAKDOWN'!F16,"Unit Price Reduction ("&TEXT('2_BOM_BREAKDOWN'!F16,"#,##0.00")&" ➔ "&TEXT('2_BOM_BREAKDOWN'!G16,"#,##0.00")&" THB)",IF('2_BOM_BREAKDOWN'!I16>'2_BOM_BREAKDOWN'!H16,"Loss % Increase ("&TEXT('2_BOM_BREAKDOWN'!H16,"0.0%")&" ➔ "&TEXT('2_BOM_BREAKDOWN'!I16,"0.0%")&")",IF('2_BOM_BREAKDOWN'!I16<'2_BOM_BREAKDOWN'!H16,"Loss % Reduction ("&TEXT('2_BOM_BREAKDOWN'!H16,"0.0%")&" ➔ "&TEXT('2_BOM_BREAKDOWN'!I16,"0.0%")&")",""))))),"") | E15: =IFERROR(IF(OR('2_BOM_BREAKDOWN'!C16="",""),"",IF('2_BOM_BREAKDOWN'!G16<>'2_BOM_BREAKDOWN'!F16,'2_BOM_BREAKDOWN'!F16,IF('2_BOM_BREAKDOWN'!I16<>'2_BOM_BREAKDOWN'!H16,'2_BOM_BREAKDOWN'!H16,""))),"") | F15: =IFERROR(IF(OR('2_BOM_BREAKDOWN'!C16="",""),"",IF('2_BOM_BREAKDOWN'!G16<>'2_BOM_BREAKDOWN'!F16,'2_BOM_BREAKDOWN'!G16,IF('2_BOM_BREAKDOWN'!I16<>'2_BOM_BREAKDOWN'!H16,'2_BOM_BREAKDOWN'!I16,""))),"") | G15: =IFERROR(IF(OR('2_BOM_BREAKDOWN'!C16="",'2_BOM_BREAKDOWN'!H35=""),"",'2_BOM_BREAKDOWN'!H35),"") | H15: =IFERROR(IF(OR(G15="",G15<=0), "", G15+(55-A15)*0.00000001), "")
... A19: 16 | B19: =IFERROR(IF('2_BOM_BREAKDOWN'!C20="","","Direct Material"),"") | C19: =IFERROR(IF('2_BOM_BREAKDOWN'!C20="","",'2_BOM_BREAKDOWN'!C20),"") | D19: =IFERROR(IF(OR('2_BOM_BREAKDOWN'!C20="",""),"",IF('2_BOM_BREAKDOWN'!G20>'2_BOM_BREAKDOWN'!F20,"Unit Price Inflation ("&TEXT('2_BOM_BREAKDOWN'!F20,"#,##0.00")&" ➔ "&TEXT('2_BOM_BREAKDOWN'!G20,"#,##0.00")&" THB)",IF('2_BOM_BREAKDOWN'!G20<'2_BOM_BREAKDOWN'!F20,"Unit Price Reduction ("&TEXT('2_BOM_BREAKDOWN'!F20,"#,##0.00")&" ➔ "&TEXT('2_BOM_BREAKDOWN'!G20,"#,##0.00")&" THB)",IF('2_BOM_BREAKDOWN'!I20>'2_BOM_BREAKDOWN'!H20,"Loss % Increase ("&TEXT('2_BOM_BREAKDOWN'!H20,"0.0%")&" ➔ "&TEXT('2_BOM_BREAKDOWN'!I20,"0.0%")&")",IF('2_BOM_BREAKDOWN'!I20<'2_BOM_BREAKDOWN'!H20,"Loss % Reduction ("&TEXT('2_BOM_BREAKDOWN'!H20,"0.0%")&" ➔ "&TEXT('2_BOM_BREAKDOWN'!I20,"0.0%")&")",""))))),"") | E19: =IFERROR(IF(OR('2_BOM_BREAKDOWN'!C20="",""),"",IF('2_BOM_BREAKDOWN'!G20<>'2_BOM_BREAKDOWN'!F20,'2_BOM_BREAKDOWN'!F20,IF('2_BOM_BREAKDOWN'!I20<>'2_BOM_BREAKDOWN'!H20,'2_BOM_BREAKDOWN'!H20,""))),"") | F19: =IFERROR(IF(OR('2_BOM_BREAKDOWN'!C20="",""),"",IF('2_BOM_BREAKDOWN'!G20<>'2_BOM_BREAKDOWN'!F20,'2_BOM_BREAKDOWN'!G20,IF('2_BOM_BREAKDOWN'!I20<>'2_BOM_BREAKDOWN'!H20,'2_BOM_BREAKDOWN'!I20,""))),"") | G19: =IFERROR(IF(OR('2_BOM_BREAKDOWN'!C20="",'2_BOM_BREAKDOWN'!H39=""),"",'2_BOM_BREAKDOWN'!H39),"") | H19: =IFERROR(IF(OR(G19="",G19<=0), "", G19+(55-A19)*0.00000001), "")
A20: 17 | B20: =IFERROR(IF('3_ROUTING_BREAKDOWN'!B5="","",'3_ROUTING_BREAKDOWN'!B5),"") | C20: =IFERROR(IF('3_ROUTING_BREAKDOWN'!C5="","",'3_ROUTING_BREAKDOWN'!C5),"") | D20: =IFERROR(IF(OR('3_ROUTING_BREAKDOWN'!C5="",""),"",IF('3_ROUTING_BREAKDOWN'!I5<'3_ROUTING_BREAKDOWN'!H5,"Yield Drop ("&TEXT('3_ROUTING_BREAKDOWN'!H5,"0.0%")&" ➔ "&TEXT('3_ROUTING_BREAKDOWN'!I5,"0.0%")&")",IF('3_ROUTING_BREAKDOWN'!I5>'3_ROUTING_BREAKDOWN'!H5,"Yield Improvement ("&TEXT('3_ROUTING_BREAKDOWN'!H5,"0.0%")&" ➔ "&TEXT('3_ROUTING_BREAKDOWN'!I5,"0.0%")&")",IF('3_ROUTING_BREAKDOWN'!G5<'3_ROUTING_BREAKDOWN'!F5,"Capacity Drop ("&TEXT('3_ROUTING_BREAKDOWN'!F5,"#,##0")&" ➔ "&TEXT('3_ROUTING_BREAKDOWN'!G5,"#,##0")&" Unit/hr)",IF('3_ROUTING_BREAKDOWN'!G5>'3_ROUTING_BREAKDOWN'!F5,"Capacity Improvement ("&TEXT('3_ROUTING_BREAKDOWN'!F5,"#,##0")&" ➔ "&TEXT('3_ROUTING_BREAKDOWN'!G5,"#,##0")&" Unit/hr)",""))))),"") | E20: =IFERROR(IF(OR('3_ROUTING_BREAKDOWN'!C5="",""),"",IF('3_ROUTING_BREAKDOWN'!I5<>'3_ROUTING_BREAKDOWN'!H5,'3_ROUTING_BREAKDOWN'!H5,IF('3_ROUTING_BREAKDOWN'!G5<>'3_ROUTING_BREAKDOWN'!F5,'3_ROUTING_BREAKDOWN'!F5,""))),"") | F20: =IFERROR(IF(OR('3_ROUTING_BREAKDOWN'!C5="",""),"",IF('3_ROUTING_BREAKDOWN'!I5<>'3_ROUTING_BREAKDOWN'!H5,'3_ROUTING_BREAKDOWN'!I5,IF('3_ROUTING_BREAKDOWN'!G5<>'3_ROUTING_BREAKDOWN'!F5,'3_ROUTING_BREAKDOWN'!G5,""))),"") | G20: =IFERROR(IF(OR('3_ROUTING_BREAKDOWN'!C5="",'3_ROUTING_BREAKDOWN'!P47=""),"",'3_ROUTING_BREAKDOWN'!P47),"") | H20: =IFERROR(IF(OR(G20="",G20<=0), "", G20+(55-A20)*0.00000001), "")
A21: 18 | B21: =IFERROR(IF('3_ROUTING_BREAKDOWN'!B6="","",'3_ROUTING_BREAKDOWN'!B6),"") | C21: =IFERROR(IF('3_ROUTING_BREAKDOWN'!C6="","",'3_ROUTING_BREAKDOWN'!C6),"") | D21: =IFERROR(IF(OR('3_ROUTING_BREAKDOWN'!C6="",""),"",IF('3_ROUTING_BREAKDOWN'!I6<'3_ROUTING_BREAKDOWN'!H6,"Yield Drop ("&TEXT('3_ROUTING_BREAKDOWN'!H6,"0.0%")&" ➔ "&TEXT('3_ROUTING_BREAKDOWN'!I6,"0.0%")&")",IF('3_ROUTING_BREAKDOWN'!I6>'3_ROUTING_BREAKDOWN'!H6,"Yield Improvement ("&TEXT('3_ROUTING_BREAKDOWN'!H6,"0.0%")&" ➔ "&TEXT('3_ROUTING_BREAKDOWN'!I6,"0.0%")&")",IF('3_ROUTING_BREAKDOWN'!G6<'3_ROUTING_BREAKDOWN'!F6,"Capacity Drop ("&TEXT('3_ROUTING_BREAKDOWN'!F6,"#,##0")&" ➔ "&TEXT('3_ROUTING_BREAKDOWN'!G6,"#,##0")&" Unit/hr)",IF('3_ROUTING_BREAKDOWN'!G6>'3_ROUTING_BREAKDOWN'!F6,"Capacity Improvement ("&TEXT('3_ROUTING_BREAKDOWN'!F6,"#,##0")&" ➔ "&TEXT('3_ROUTING_BREAKDOWN'!G6,"#,##0")&" Unit/hr)",""))))),"") | E21: =IFERROR(IF(OR('3_ROUTING_BREAKDOWN'!C6="",""),"",IF('3_ROUTING_BREAKDOWN'!I6<>'3_ROUTING_BREAKDOWN'!H6,'3_ROUTING_BREAKDOWN'!H6,IF('3_ROUTING_BREAKDOWN'!G6<>'3_ROUTING_BREAKDOWN'!F6,'3_ROUTING_BREAKDOWN'!F6,""))),"") | F21: =IFERROR(IF(OR('3_ROUTING_BREAKDOWN'!C6="",""),"",IF('3_ROUTING_BREAKDOWN'!I6<>'3_ROUTING_BREAKDOWN'!H6,'3_ROUTING_BREAKDOWN'!I6,IF('3_ROUTING_BREAKDOWN'!G6<>'3_ROUTING_BREAKDOWN'!F6,'3_ROUTING_BREAKDOWN'!G6,""))),"") | G21: =IFERROR(IF(OR('3_ROUTING_BREAKDOWN'!C6="",'3_ROUTING_BREAKDOWN'!P48=""),"",'3_ROUTING_BREAKDOWN'!P48),"") | H21: =IFERROR(IF(OR(G21="",G21<=0), "", G21+(55-A21)*0.00000001), "")
A22: 19 | B22: =IFERROR(IF('3_ROUTING_BREAKDOWN'!B7="","",'3_ROUTING_BREAKDOWN'!B7),"") | C22: =IFERROR(IF('3_ROUTING_BREAKDOWN'!C7="","",'3_ROUTING_BREAKDOWN'!C7),"") | D22: =IFERROR(IF(OR('3_ROUTING_BREAKDOWN'!C7="",""),"",IF('3_ROUTING_BREAKDOWN'!I7<'3_ROUTING_BREAKDOWN'!H7,"Yield Drop ("&TEXT('3_ROUTING_BREAKDOWN'!H7,"0.0%")&" ➔ "&TEXT('3_ROUTING_BREAKDOWN'!I7,"0.0%")&")",IF('3_ROUTING_BREAKDOWN'!I7>'3_ROUTING_BREAKDOWN'!H7,"Yield Improvement ("&TEXT('3_ROUTING_BREAKDOWN'!H7,"0.0%")&" ➔ "&TEXT('3_ROUTING_BREAKDOWN'!I7,"0.0%")&")",IF('3_ROUTING_BREAKDOWN'!G7<'3_ROUTING_BREAKDOWN'!F7,"Capacity Drop ("&TEXT('3_ROUTING_BREAKDOWN'!F7,"#,##0")&" ➔ "&TEXT('3_ROUTING_BREAKDOWN'!G7,"#,##0")&" Unit/hr)",IF('3_ROUTING_BREAKDOWN'!G7>'3_ROUTING_BREAKDOWN'!F7,"Capacity Improvement ("&TEXT('3_ROUTING_BREAKDOWN'!F7,"#,##0")&" ➔ "&TEXT('3_ROUTING_BREAKDOWN'!G7,"#,##0")&" Unit/hr)",""))))),"") | E22: =IFERROR(IF(OR('3_ROUTING_BREAKDOWN'!C7="",""),"",IF('3_ROUTING_BREAKDOWN'!I7<>'3_ROUTING_BREAKDOWN'!H7,'3_ROUTING_BREAKDOWN'!H7,IF('3_ROUTING_BREAKDOWN'!G7<>'3_ROUTING_BREAKDOWN'!F7,'3_ROUTING_BREAKDOWN'!F7,""))),"") | F22: =IFERROR(IF(OR('3_ROUTING_BREAKDOWN'!C7="",""),"",IF('3_ROUTING_BREAKDOWN'!I7<>'3_ROUTING_BREAKDOWN'!H7,'3_ROUTING_BREAKDOWN'!I7,IF('3_ROUTING_BREAKDOWN'!G7<>'3_ROUTING_BREAKDOWN'!F7,'3_ROUTING_BREAKDOWN'!G7,""))),"") | G22: =IFERROR(IF(OR('3_ROUTING_BREAKDOWN'!C7="",'3_ROUTING_BREAKDOWN'!P49=""),"",'3_ROUTING_BREAKDOWN'!P49),"") | H22: =IFERROR(IF(OR(G22="",G22<=0), "", G22+(55-A22)*0.00000001), "")
A23: 20 | B23: =IFERROR(IF('3_ROUTING_BREAKDOWN'!B8="","",'3_ROUTING_BREAKDOWN'!B8),"") | C23: =IFERROR(IF('3_ROUTING_BREAKDOWN'!C8="","",'3_ROUTING_BREAKDOWN'!C8),"") | D23: =IFERROR(IF(OR('3_ROUTING_BREAKDOWN'!C8="",""),"",IF('3_ROUTING_BREAKDOWN'!I8<'3_ROUTING_BREAKDOWN'!H8,"Yield Drop ("&TEXT('3_ROUTING_BREAKDOWN'!H8,"0.0%")&" ➔ "&TEXT('3_ROUTING_BREAKDOWN'!I8,"0.0%")&")",IF('3_ROUTING_BREAKDOWN'!I8>'3_ROUTING_BREAKDOWN'!H8,"Yield Improvement ("&TEXT('3_ROUTING_BREAKDOWN'!H8,"0.0%")&" ➔ "&TEXT('3_ROUTING_BREAKDOWN'!I8,"0.0%")&")",IF('3_ROUTING_BREAKDOWN'!G8<'3_ROUTING_BREAKDOWN'!F8,"Capacity Drop ("&TEXT('3_ROUTING_BREAKDOWN'!F8,"#,##0")&" ➔ "&TEXT('3_ROUTING_BREAKDOWN'!G8,"#,##0")&" Unit/hr)",IF('3_ROUTING_BREAKDOWN'!G8>'3_ROUTING_BREAKDOWN'!F8,"Capacity Improvement ("&TEXT('3_ROUTING_BREAKDOWN'!F8,"#,##0")&" ➔ "&TEXT('3_ROUTING_BREAKDOWN'!G8,"#,##0")&" Unit/hr)",""))))),"") | E23: =IFERROR(IF(OR('3_ROUTING_BREAKDOWN'!C8="",""),"",IF('3_ROUTING_BREAKDOWN'!I8<>'3_ROUTING_BREAKDOWN'!H8,'3_ROUTING_BREAKDOWN'!H8,IF('3_ROUTING_BREAKDOWN'!G8<>'3_ROUTING_BREAKDOWN'!F8,'3_ROUTING_BREAKDOWN'!F8,""))),"") | F23: =IFERROR(IF(OR('3_ROUTING_BREAKDOWN'!C8="",""),"",IF('3_ROUTING_BREAKDOWN'!I8<>'3_ROUTING_BREAKDOWN'!H8,'3_ROUTING_BREAKDOWN'!I8,IF('3_ROUTING_BREAKDOWN'!G8<>'3_ROUTING_BREAKDOWN'!F8,'3_ROUTING_BREAKDOWN'!G8,""))),"") | G23: =IFERROR(IF(OR('3_ROUTING_BREAKDOWN'!C8="",'3_ROUTING_BREAKDOWN'!P50=""),"",'3_ROUTING_BREAKDOWN'!P50),"") | H23: =IFERROR(IF(OR(G23="",G23<=0), "", G23+(55-A23)*0.00000001), "")
A24: 21 | B24: =IFERROR(IF('3_ROUTING_BREAKDOWN'!B9="","",'3_ROUTING_BREAKDOWN'!B9),"") | C24: =IFERROR(IF('3_ROUTING_BREAKDOWN'!C9="","",'3_ROUTING_BREAKDOWN'!C9),"") | D24: =IFERROR(IF(OR('3_ROUTING_BREAKDOWN'!C9="",""),"",IF('3_ROUTING_BREAKDOWN'!I9<'3_ROUTING_BREAKDOWN'!H9,"Yield Drop ("&TEXT('3_ROUTING_BREAKDOWN'!H9,"0.0%")&" ➔ "&TEXT('3_ROUTING_BREAKDOWN'!I9,"0.0%")&")",IF('3_ROUTING_BREAKDOWN'!I9>'3_ROUTING_BREAKDOWN'!H9,"Yield Improvement ("&TEXT('3_ROUTING_BREAKDOWN'!H9,"0.0%")&" ➔ "&TEXT('3_ROUTING_BREAKDOWN'!I9,"0.0%")&")",IF('3_ROUTING_BREAKDOWN'!G9<'3_ROUTING_BREAKDOWN'!F9,"Capacity Drop ("&TEXT('3_ROUTING_BREAKDOWN'!F9,"#,##0")&" ➔ "&TEXT('3_ROUTING_BREAKDOWN'!G9,"#,##0")&" Unit/hr)",IF('3_ROUTING_BREAKDOWN'!G9>'3_ROUTING_BREAKDOWN'!F9,"Capacity Improvement ("&TEXT('3_ROUTING_BREAKDOWN'!F9,"#,##0")&" ➔ "&TEXT('3_ROUTING_BREAKDOWN'!G9,"#,##0")&" Unit/hr)",""))))),"") | E24: =IFERROR(IF(OR('3_ROUTING_BREAKDOWN'!C9="",""),"",IF('3_ROUTING_BREAKDOWN'!I9<>'3_ROUTING_BREAKDOWN'!H9,'3_ROUTING_BREAKDOWN'!H9,IF('3_ROUTING_BREAKDOWN'!G9<>'3_ROUTING_BREAKDOWN'!F9,'3_ROUTING_BREAKDOWN'!F9,""))),"") | F24: =IFERROR(IF(OR('3_ROUTING_BREAKDOWN'!C9="",""),"",IF('3_ROUTING_BREAKDOWN'!I9<>'3_ROUTING_BREAKDOWN'!H9,'3_ROUTING_BREAKDOWN'!I9,IF('3_ROUTING_BREAKDOWN'!G9<>'3_ROUTING_BREAKDOWN'!F9,'3_ROUTING_BREAKDOWN'!G9,""))),"") | G24: =IFERROR(IF(OR('3_ROUTING_BREAKDOWN'!C9="",'3_ROUTING_BREAKDOWN'!P51=""),"",'3_ROUTING_BREAKDOWN'!P51),"") | H24: =IFERROR(IF(OR(G24="",G24<=0), "", G24+(55-A24)*0.00000001), "")
A25: 22 | B25: =IFERROR(IF('3_ROUTING_BREAKDOWN'!B10="","",'3_ROUTING_BREAKDOWN'!B10),"") | C25: =IFERROR(IF('3_ROUTING_BREAKDOWN'!C10="","",'3_ROUTING_BREAKDOWN'!C10),"") | D25: =IFERROR(IF(OR('3_ROUTING_BREAKDOWN'!C10="",""),"",IF('3_ROUTING_BREAKDOWN'!I10<'3_ROUTING_BREAKDOWN'!H10,"Yield Drop ("&TEXT('3_ROUTING_BREAKDOWN'!H10,"0.0%")&" ➔ "&TEXT('3_ROUTING_BREAKDOWN'!I10,"0.0%")&")",IF('3_ROUTING_BREAKDOWN'!I10>'3_ROUTING_BREAKDOWN'!H10,"Yield Improvement ("&TEXT('3_ROUTING_BREAKDOWN'!H10,"0.0%")&" ➔ "&TEXT('3_ROUTING_BREAKDOWN'!I10,"0.0%")&")",IF('3_ROUTING_BREAKDOWN'!G10<'3_ROUTING_BREAKDOWN'!F10,"Capacity Drop ("&TEXT('3_ROUTING_BREAKDOWN'!F10,"#,##0")&" ➔ "&TEXT('3_ROUTING_BREAKDOWN'!G10,"#,##0")&" Unit/hr)",IF('3_ROUTING_BREAKDOWN'!G10>'3_ROUTING_BREAKDOWN'!F10,"Capacity Improvement ("&TEXT('3_ROUTING_BREAKDOWN'!F10,"#,##0")&" ➔ "&TEXT('3_ROUTING_BREAKDOWN'!G10,"#,##0")&" Unit/hr)",""))))),"") | E25: =IFERROR(IF(OR('3_ROUTING_BREAKDOWN'!C10="",""),"",IF('3_ROUTING_BREAKDOWN'!I10<>'3_ROUTING_BREAKDOWN'!H10,'3_ROUTING_BREAKDOWN'!H10,IF('3_ROUTING_BREAKDOWN'!G10<>'3_ROUTING_BREAKDOWN'!F10,'3_ROUTING_BREAKDOWN'!F10,""))),"") | F25: =IFERROR(IF(OR('3_ROUTING_BREAKDOWN'!C10="",""),"",IF('3_ROUTING_BREAKDOWN'!I10<>'3_ROUTING_BREAKDOWN'!H10,'3_ROUTING_BREAKDOWN'!I10,IF('3_ROUTING_BREAKDOWN'!G10<>'3_ROUTING_BREAKDOWN'!F10,'3_ROUTING_BREAKDOWN'!G10,""))),"") | G25: =IFERROR(IF(OR('3_ROUTING_BREAKDOWN'!C10="",'3_ROUTING_BREAKDOWN'!P52=""),"",'3_ROUTING_BREAKDOWN'!P52),"") | H25: =IFERROR(IF(OR(G25="",G25<=0), "", G25+(55-A25)*0.00000001), "")
A26: 23 | B26: =IFERROR(IF('3_ROUTING_BREAKDOWN'!B11="","",'3_ROUTING_BREAKDOWN'!B11),"") | C26: =IFERROR(IF('3_ROUTING_BREAKDOWN'!C11="","",'3_ROUTING_BREAKDOWN'!C11),"") | D26: =IFERROR(IF(OR('3_ROUTING_BREAKDOWN'!C11="",""),"",IF('3_ROUTING_BREAKDOWN'!I11<'3_ROUTING_BREAKDOWN'!H11,"Yield Drop ("&TEXT('3_ROUTING_BREAKDOWN'!H11,"0.0%")&" ➔ "&TEXT('3_ROUTING_BREAKDOWN'!I11,"0.0%")&")",IF('3_ROUTING_BREAKDOWN'!I11>'3_ROUTING_BREAKDOWN'!H11,"Yield Improvement ("&TEXT('3_ROUTING_BREAKDOWN'!H11,"0.0%")&" ➔ "&TEXT('3_ROUTING_BREAKDOWN'!I11,"0.0%")&")",IF('3_ROUTING_BREAKDOWN'!G11<'3_ROUTING_BREAKDOWN'!F11,"Capacity Drop ("&TEXT('3_ROUTING_BREAKDOWN'!F11,"#,##0")&" ➔ "&TEXT('3_ROUTING_BREAKDOWN'!G11,"#,##0")&" Unit/hr)",IF('3_ROUTING_BREAKDOWN'!G11>'3_ROUTING_BREAKDOWN'!F11,"Capacity Improvement ("&TEXT('3_ROUTING_BREAKDOWN'!F11,"#,##0")&" ➔ "&TEXT('3_ROUTING_BREAKDOWN'!G11,"#,##0")&" Unit/hr)",""))))),"") | E26: =IFERROR(IF(OR('3_ROUTING_BREAKDOWN'!C11="",""),"",IF('3_ROUTING_BREAKDOWN'!I11<>'3_ROUTING_BREAKDOWN'!H11,'3_ROUTING_BREAKDOWN'!H11,IF('3_ROUTING_BREAKDOWN'!G11<>'3_ROUTING_BREAKDOWN'!F11,'3_ROUTING_BREAKDOWN'!F11,""))),"") | F26: =IFERROR(IF(OR('3_ROUTING_BREAKDOWN'!C11="",""),"",IF('3_ROUTING_BREAKDOWN'!I11<>'3_ROUTING_BREAKDOWN'!H11,'3_ROUTING_BREAKDOWN'!I11,IF('3_ROUTING_BREAKDOWN'!G11<>'3_ROUTING_BREAKDOWN'!F11,'3_ROUTING_BREAKDOWN'!G11,""))),"") | G26: =IFERROR(IF(OR('3_ROUTING_BREAKDOWN'!C11="",'3_ROUTING_BREAKDOWN'!P53=""),"",'3_ROUTING_BREAKDOWN'!P53),"") | H26: =IFERROR(IF(OR(G26="",G26<=0), "", G26+(55-A26)*0.00000001), "")
A27: 24 | B27: =IFERROR(IF('3_ROUTING_BREAKDOWN'!B12="","",'3_ROUTING_BREAKDOWN'!B12),"") | C27: =IFERROR(IF('3_ROUTING_BREAKDOWN'!C12="","",'3_ROUTING_BREAKDOWN'!C12),"") | D27: =IFERROR(IF(OR('3_ROUTING_BREAKDOWN'!C12="",""),"",IF('3_ROUTING_BREAKDOWN'!I12<'3_ROUTING_BREAKDOWN'!H12,"Yield Drop ("&TEXT('3_ROUTING_BREAKDOWN'!H12,"0.0%")&" ➔ "&TEXT('3_ROUTING_BREAKDOWN'!I12,"0.0%")&")",IF('3_ROUTING_BREAKDOWN'!I12>'3_ROUTING_BREAKDOWN'!H12,"Yield Improvement ("&TEXT('3_ROUTING_BREAKDOWN'!H12,"0.0%")&" ➔ "&TEXT('3_ROUTING_BREAKDOWN'!I12,"0.0%")&")",IF('3_ROUTING_BREAKDOWN'!G12<'3_ROUTING_BREAKDOWN'!F12,"Capacity Drop ("&TEXT('3_ROUTING_BREAKDOWN'!F12,"#,##0")&" ➔ "&TEXT('3_ROUTING_BREAKDOWN'!G12,"#,##0")&" Unit/hr)",IF('3_ROUTING_BREAKDOWN'!G12>'3_ROUTING_BREAKDOWN'!F12,"Capacity Improvement ("&TEXT('3_ROUTING_BREAKDOWN'!F12,"#,##0")&" ➔ "&TEXT('3_ROUTING_BREAKDOWN'!G12,"#,##0")&" Unit/hr)",""))))),"") | E27: =IFERROR(IF(OR('3_ROUTING_BREAKDOWN'!C12="",""),"",IF('3_ROUTING_BREAKDOWN'!I12<>'3_ROUTING_BREAKDOWN'!H12,'3_ROUTING_BREAKDOWN'!H12,IF('3_ROUTING_BREAKDOWN'!G12<>'3_ROUTING_BREAKDOWN'!F12,'3_ROUTING_BREAKDOWN'!F12,""))),"") | F27: =IFERROR(IF(OR('3_ROUTING_BREAKDOWN'!C12="",""),"",IF('3_ROUTING_BREAKDOWN'!I12<>'3_ROUTING_BREAKDOWN'!H12,'3_ROUTING_BREAKDOWN'!I12,IF('3_ROUTING_BREAKDOWN'!G12<>'3_ROUTING_BREAKDOWN'!F12,'3_ROUTING_BREAKDOWN'!G12,""))),"") | G27: =IFERROR(IF(OR('3_ROUTING_BREAKDOWN'!C12="",'3_ROUTING_BREAKDOWN'!P54=""),"",'3_ROUTING_BREAKDOWN'!P54),"") | H27: =IFERROR(IF(OR(G27="",G27<=0), "", G27+(55-A27)*0.00000001), "")
A28: 25 | B28: =IFERROR(IF('3_ROUTING_BREAKDOWN'!B13="","",'3_ROUTING_BREAKDOWN'!B13),"") | C28: =IFERROR(IF('3_ROUTING_BREAKDOWN'!C13="","",'3_ROUTING_BREAKDOWN'!C13),"") | D28: =IFERROR(IF(OR('3_ROUTING_BREAKDOWN'!C13="",""),"",IF('3_ROUTING_BREAKDOWN'!I13<'3_ROUTING_BREAKDOWN'!H13,"Yield Drop ("&TEXT('3_ROUTING_BREAKDOWN'!H13,"0.0%")&" ➔ "&TEXT('3_ROUTING_BREAKDOWN'!I13,"0.0%")&")",IF('3_ROUTING_BREAKDOWN'!I13>'3_ROUTING_BREAKDOWN'!H13,"Yield Improvement ("&TEXT('3_ROUTING_BREAKDOWN'!H13,"0.0%")&" ➔ "&TEXT('3_ROUTING_BREAKDOWN'!I13,"0.0%")&")",IF('3_ROUTING_BREAKDOWN'!G13<'3_ROUTING_BREAKDOWN'!F13,"Capacity Drop ("&TEXT('3_ROUTING_BREAKDOWN'!F13,"#,##0")&" ➔ "&TEXT('3_ROUTING_BREAKDOWN'!G13,"#,##0")&" Unit/hr)",IF('3_ROUTING_BREAKDOWN'!G13>'3_ROUTING_BREAKDOWN'!F13,"Capacity Improvement ("&TEXT('3_ROUTING_BREAKDOWN'!F13,"#,##0")&" ➔ "&TEXT('3_ROUTING_BREAKDOWN'!G13,"#,##0")&" Unit/hr)",""))))),"") | E28: =IFERROR(IF(OR('3_ROUTING_BREAKDOWN'!C13="",""),"",IF('3_ROUTING_BREAKDOWN'!I13<>'3_ROUTING_BREAKDOWN'!H13,'3_ROUTING_BREAKDOWN'!H13,IF('3_ROUTING_BREAKDOWN'!G13<>'3_ROUTING_BREAKDOWN'!F13,'3_ROUTING_BREAKDOWN'!F13,""))),"") | F28: =IFERROR(IF(OR('3_ROUTING_BREAKDOWN'!C13="",""),"",IF('3_ROUTING_BREAKDOWN'!I13<>'3_ROUTING_BREAKDOWN'!H13,'3_ROUTING_BREAKDOWN'!I13,IF('3_ROUTING_BREAKDOWN'!G13<>'3_ROUTING_BREAKDOWN'!F13,'3_ROUTING_BREAKDOWN'!G13,""))),"") | G28: =IFERROR(IF(OR('3_ROUTING_BREAKDOWN'!C13="",'3_ROUTING_BREAKDOWN'!P55=""),"",'3_ROUTING_BREAKDOWN'!P55),"") | H28: =IFERROR(IF(OR(G28="",G28<=0), "", G28+(55-A28)*0.00000001), "")
A29: 26 | B29: =IFERROR(IF('3_ROUTING_BREAKDOWN'!B14="","",'3_ROUTING_BREAKDOWN'!B14),"") | C29: =IFERROR(IF('3_ROUTING_BREAKDOWN'!C14="","",'3_ROUTING_BREAKDOWN'!C14),"") | D29: =IFERROR(IF(OR('3_ROUTING_BREAKDOWN'!C14="",""),"",IF('3_ROUTING_BREAKDOWN'!I14<'3_ROUTING_BREAKDOWN'!H14,"Yield Drop ("&TEXT('3_ROUTING_BREAKDOWN'!H14,"0.0%")&" ➔ "&TEXT('3_ROUTING_BREAKDOWN'!I14,"0.0%")&")",IF('3_ROUTING_BREAKDOWN'!I14>'3_ROUTING_BREAKDOWN'!H14,"Yield Improvement ("&TEXT('3_ROUTING_BREAKDOWN'!H14,"0.0%")&" ➔ "&TEXT('3_ROUTING_BREAKDOWN'!I14,"0.0%")&")",IF('3_ROUTING_BREAKDOWN'!G14<'3_ROUTING_BREAKDOWN'!F14,"Capacity Drop ("&TEXT('3_ROUTING_BREAKDOWN'!F14,"#,##0")&" ➔ "&TEXT('3_ROUTING_BREAKDOWN'!G14,"#,##0")&" Unit/hr)",IF('3_ROUTING_BREAKDOWN'!G14>'3_ROUTING_BREAKDOWN'!F14,"Capacity Improvement ("&TEXT('3_ROUTING_BREAKDOWN'!F14,"#,##0")&" ➔ "&TEXT('3_ROUTING_BREAKDOWN'!G14,"#,##0")&" Unit/hr)",""))))),"") | E29: =IFERROR(IF(OR('3_ROUTING_BREAKDOWN'!C14="",""),"",IF('3_ROUTING_BREAKDOWN'!I14<>'3_ROUTING_BREAKDOWN'!H14,'3_ROUTING_BREAKDOWN'!H14,IF('3_ROUTING_BREAKDOWN'!G14<>'3_ROUTING_BREAKDOWN'!F14,'3_ROUTING_BREAKDOWN'!F14,""))),"") | F29: =IFERROR(IF(OR('3_ROUTING_BREAKDOWN'!C14="",""),"",IF('3_ROUTING_BREAKDOWN'!I14<>'3_ROUTING_BREAKDOWN'!H14,'3_ROUTING_BREAKDOWN'!I14,IF('3_ROUTING_BREAKDOWN'!G14<>'3_ROUTING_BREAKDOWN'!F14,'3_ROUTING_BREAKDOWN'!G14,""))),"") | G29: =IFERROR(IF(OR('3_ROUTING_BREAKDOWN'!C14="",'3_ROUTING_BREAKDOWN'!P56=""),"",'3_ROUTING_BREAKDOWN'!P56),"") | H29: =IFERROR(IF(OR(G29="",G29<=0), "", G29+(55-A29)*0.00000001), "")
A30: 27 | B30: =IFERROR(IF('3_ROUTING_BREAKDOWN'!B15="","",'3_ROUTING_BREAKDOWN'!B15),"") | C30: =IFERROR(IF('3_ROUTING_BREAKDOWN'!C15="","",'3_ROUTING_BREAKDOWN'!C15),"") | D30: =IFERROR(IF(OR('3_ROUTING_BREAKDOWN'!C15="",""),"",IF('3_ROUTING_BREAKDOWN'!I15<'3_ROUTING_BREAKDOWN'!H15,"Yield Drop ("&TEXT('3_ROUTING_BREAKDOWN'!H15,"0.0%")&" ➔ "&TEXT('3_ROUTING_BREAKDOWN'!I15,"0.0%")&")",IF('3_ROUTING_BREAKDOWN'!I15>'3_ROUTING_BREAKDOWN'!H15,"Yield Improvement ("&TEXT('3_ROUTING_BREAKDOWN'!H15,"0.0%")&" ➔ "&TEXT('3_ROUTING_BREAKDOWN'!I15,"0.0%")&")",IF('3_ROUTING_BREAKDOWN'!G15<'3_ROUTING_BREAKDOWN'!F15,"Capacity Drop ("&TEXT('3_ROUTING_BREAKDOWN'!F15,"#,##0")&" ➔ "&TEXT('3_ROUTING_BREAKDOWN'!G15,"#,##0")&" Unit/hr)",IF('3_ROUTING_BREAKDOWN'!G15>'3_ROUTING_BREAKDOWN'!F15,"Capacity Improvement ("&TEXT('3_ROUTING_BREAKDOWN'!F15,"#,##0")&" ➔ "&TEXT('3_ROUTING_BREAKDOWN'!G15,"#,##0")&" Unit/hr)",""))))),"") | E30: =IFERROR(IF(OR('3_ROUTING_BREAKDOWN'!C15="",""),"",IF('3_ROUTING_BREAKDOWN'!I15<>'3_ROUTING_BREAKDOWN'!H15,'3_ROUTING_BREAKDOWN'!H15,IF('3_ROUTING_BREAKDOWN'!G15<>'3_ROUTING_BREAKDOWN'!F15,'3_ROUTING_BREAKDOWN'!F15,""))),"") | F30: =IFERROR(IF(OR('3_ROUTING_BREAKDOWN'!C15="",""),"",IF('3_ROUTING_BREAKDOWN'!I15<>'3_ROUTING_BREAKDOWN'!H15,'3_ROUTING_BREAKDOWN'!I15,IF('3_ROUTING_BREAKDOWN'!G15<>'3_ROUTING_BREAKDOWN'!F15,'3_ROUTING_BREAKDOWN'!G15,""))),"") | G30: =IFERROR(IF(OR('3_ROUTING_BREAKDOWN'!C15="",'3_ROUTING_BREAKDOWN'!P57=""),"",'3_ROUTING_BREAKDOWN'!P57),"") | H30: =IFERROR(IF(OR(G30="",G30<=0), "", G30+(55-A30)*0.00000001), "")
